Workbook
Name ChestCoef: 'Model Coefficients'!$G$2:$K$13
Name ExternalData_1: 'Odds Ratios'!$A$2:$D$9
Name ExternalData_2: 'Odds Ratios'!$A$13:$D$20
Name ExternalData_3: 'Odds Ratios'!$A$24:$D$31
Name HeadCoef: 'Model Coefficients'!$A$2:$E$13
Name LowerExtremityCoef: 'Model Coefficients'!$M$2:$Q$13
Name ModelTypes: 'Model Coefficients'!$B$2:$E$2

Sheet Odds Ratios
A1: Head AIS 3+ | F1: Head AIS 3+ | K1: Head AIS 3+ | P1: Head AIS 3+
A2: Frontal (0 degree) | F2: Oblique Combined (330,340,350,10,20,30) | K2: Oblique Left Direction (330,340,350) | P2: Oblique Right Direction (10,20,30)
A3: Effect | B3: Odds Ratio | C3: 95% Wald CI | F3: Effect | G3: Odds Ratio | H3: 95% Wald CI | K3: Effect | L3: Odds Ratio | M3: 95% Wald CI | P3: Effect | Q3: Odds Ratio | R3: 95% Wald CI
A4: log(delta-V mph) | B4: 11.12 | C4: 4.04 | D4: 30.611 | E4: ** | F4: log(delta-V mph) | G4: 11.413 | H4: 3.503 | I4: 37.189 | J4: ** | K4: log(delta-V mph) | L4: 11.008 | M4: 2.84 | N4: 42.67 | O4: ** | P4: LDVMPH | Q4: 11.01 | R4: 1.444 | S4: 83.968 | T4: *
A5: AGE 36-65 vs 18-35 | B5: 0.944 | C5: 0.36 | D5: 2.474 | F5: AGE 36-65 vs 18-35 | G5: 1.576 | H5: 0.52 | I5: 4.776 | K5: AGE 36-65 vs 18-35 | L5: 1.089 | M5: 0.694 | N5: 1.711 | P5: AGE 36-65 vs 18-35 | Q5: 3.521 | R5: 0.437 | S5: 28.386
A6: AGE 66+ vs 18-35 | B6: 1.39 | C6: 0.483 | D6: 4.004 | F6: AGE 66+ vs 18-35 | G6: 0.909 | H6: 0.207 | I6: 3.986 | K6: AGE 66+ vs 18-35 | L6: 0.678 | M6: 0.083 | N6: 5.542 | P6: AGE 66+ vs 18-35 | Q6: 2.624 | R6: 0.277 | S6: 24.869
A7: HEIGHT (per centimeter increase) | B7: 1.031 | C7: 0.985 | D7: 1.078 | F7: HEIGHT (per centimeter increase) | G7: 1.012 | H7: 0.927 | I7: 1.105 | K7: HEIGHT (per centimeter increase) | L7: 0.987 | M7: 0.906 | N7: 1.074 | P7: HEIGHT (per centimeter increase) | Q7: 1.071 | R7: 1.037 | S7: 1.105 | T7: **
A8: BMI (per unit increase) | B8: 1.017 | C8: 0.943 | D8: 1.098 | F8: BMI (per unit increase) | G8: 1.05 | H8: 1.001 | I8: 1.102 | J8: * | K8: BMI (per unit increase) | L8: 1.061 | M8: 1.025 | N8: 1.098 | O8: ** | P8: BMI (per unit increase) | Q8: 1.001 | R8: 0.885 | S8: 1.132
A9: SEX F vs M | B9: 0.742 | C9: 0.287 | D9: 1.914 | F9: SEX F vs M | G9: 0.38 | H9: 0.12 | I9: 1.203 | K9: SEX F vs M | L9: 0.287 | M9: 0.118 | N9: 0.699 | O9: ** | P9: SEX F vs M | Q9: 0.775 | R9: 0.098 | S9: 6.143
F10: PDOF R vs L | G10: 0.633 | H10: 0.149 | I10: 2.684
A12: Chest AIS 3+ | F12: Chest AIS 3+ | K12: Chest AIS 3+ | P12: Chest AIS 3+
A13: Frontal (0 degree) | F13: Oblique Combined (330,340,350,10,20,30) | K13: Oblique Left Direction (330,340,350) | P13: Oblique Right Direction (10,20,30)
A14: Effect | B14: Odds Ratio | C14: 95% Wald CI | F14: Effect | G14: Odds Ratio | H14: 95% Wald CI | K14: Effect | L14: Odds Ratio | M14: 95% Wald CI | P14: Effect | Q14: Odds Ratio | R14: 95% Wald CI
A15: log(delta-V mph) | B15: 9.414 | C15: 4.479 | D15: 19.788 | E15: ** | F15: log(delta-V mph) | G15: 17.6 | H15: 5.764 | I15: 53.739 | J15: ** | K15: log(delta-V mph) | L15: 12.067 | M15: 2.137 | N15: 68.15 | O15: ** | P15: LDVMPH | Q15: 33.441 | R15: 6.116 | S15: 182.851 | T15: **
A16: AGE 36-65 vs 18-35 | B16: 4.925 | C16: 2.673 | D16: 9.076 | E16: ** | F16: AGE 36-65 vs 18-35 | G16: 3.577 | H16: 1.62 | I16: 7.9 | J16: ** | K16: AGE 36-65 vs 18-35 | L16: 3.522 | M16: 1.124 | N16: 11.034 | P16: AGE 36-65 vs 18-35 | Q16: 4.055 | R16: 1.985 | S16: 8.281 | T16: **
A17: AGE 66+ vs 18-35 | B17: 27.27 | C17: 7.686 | D17: 96.758 | F17: AGE 66+ vs 18-35 | G17: 6.3 | H17: 2.414 | I17: 16.441 | K17: AGE 66+ vs 18-35 | L17: 1.505 | M17: 0.531 | N17: 4.266 | P17: AGE 66+ vs 18-35 | Q17: 18.128 | R17: 5.275 | S17: 62.303
A18: HEIGHT (per centimeter increase) | B18: 1.013 | C18: 0.966 | D18: 1.062 | F18: HEIGHT (per centimeter increase) | G18: 1.02 | H18: 0.992 | I18: 1.049 | K18: HEIGHT (per centimeter increase) | L18: 1.013 | M18: 0.955 | N18: 1.074 | P18: HEIGHT (per centimeter increase) | Q18: 1.031 | R18: 0.999 | S18: 1.064
A19: BMI (per unit increase) | B19: 1.054 | C19: 1.018 | D19: 1.092 | E19: ** | F19: BMI (per unit increase) | G19: 1.001 | H19: 0.957 | I19: 1.047 | K19: BMI (per unit increase) | L19: 0.991 | M19: 0.922 | N19: 1.065 | P19: BMI (per unit increase) | Q19: 1 | R19: 0.958 | S19: 1.043
A20: SEX F vs M | B20: 2.549 | C20: 0.993 | D20: 6.545 | F20: SEX F vs M | G20: 0.928 | H20: 0.353 | I20: 2.438 | K20: SEX F vs M | L20: 0.735 | M20: 0.157 | N20: 3.434 | P20: SEX F vs M | Q20: 1.471 | R20: 0.5 | S20: 4.329
F21: PDOF R vs L | G21: 1.245 | H21: 0.529 | I21: 2.934
A23: Lower Extremity AIS 2+ | F23: Lower Extremity AIS 2+ | K23: Lower Extremity AIS 2+ | P23: Lower Extremity AIS 2+
A24: Frontal (0 degree) | F24: Oblique Combined (330,340,350,10,20,30) | K24: Oblique Left Direction (330,340,350) | P24: Oblique Right Direction (10,20,30)
A25: Effect | B25: Odds Ratio | C25: 95% Wald CI | F25: Effect | G25: Odds Ratio | H25: 95% Wald CI | K25: Effect | L25: Odds Ratio | M25: 95% Wald CI | P25: Effect | Q25: Odds Ratio | R25: 95% Wald CI
A26: log(delta-V mph) | B26: 24.939 | C26: 11.15 | D26: 55.783 | E26: ** | F26: log(delta-V mph) | G26: 18.636 | H26: 8.403 | I26: 41.331 | J26: ** | K26: log(delta-V mph) | L26: 12.736 | M26: 4.621 | N26: 35.098 | O26: ** | P26: LDVMPH | Q26: 32.829 | R26: 11.503 | S26: 93.689 | T26: **
A27: AGE 36-65 vs 18-35 | B27: 1.087 | C27: 0.322 | D27: 3.666 | F27: AGE 36-65 vs 18-35 | G27: 2.033 | H27: 1.024 | I27: 4.034 | J27: ** | K27: AGE 36-65 vs 18-35 | L27: 1.958 | M27: 1.023 | N27: 3.747 | O27: * | P27: AGE 36-65 vs 18-35 | Q27: 2.119 | R27: 0.85 | S27: 5.285 | T27: *
A28: AGE 66+ vs 18-35 | B28: 2.504 | C28: 0.997 | D28: 6.287 | F28: AGE 66+ vs 18-35 | G28: 3.824 | H28: 1.603 | I28: 9.122 | K28: AGE 66+ vs 18-35 | L28: 2.019 | M28: 0.581 | N28: 7.019 | P28: AGE 66+ vs 18-35 | Q28: 7.376 | R28: 1.728 | S28: 31.482
A29: HEIGHT (per centimeter increase) | B29: 0.982 | C29: 0.94 | D29: 1.026 | F29: HEIGHT (per centimeter increase) | G29: 0.98 | H29: 0.932 | I29: 1.031 | K29: HEIGHT (per centimeter increase) | L29: 1 | M29: 0.947 | N29: 1.055 | P29: HEIGHT (per centimeter increase) | Q29: 0.956 | R29: 0.896 | S29: 1.02
A30: BMI (per unit increase) | B30: 1.071 | C30: 1.022 | D30: 1.123 | E30: ** | F30: BMI (per unit increase) | G30: 1.034 | H30: 0.977 | I30: 1.093 | K30: BMI (per unit increase) | L30: 1.043 | M30: 1 | N30: 1.089 | P30: BMI (per unit increase) | Q30: 1.018 | R30: 0.922 | S30: 1.123
A31: SEX F vs M | B31: 1.274 | C31: 0.338 | D31: 4.805 | F31: SEX F vs M | G31: 1.057 | H31: 0.508 | I31: 2.197 | K31: SEX F vs M | L31: 1.403 | M31: 0.643 | N31: 3.061 | P31: SEX F vs M | Q31: 0.849 | R31: 0.239 | S31: 3.015
F32: PDOF R vs L | G32: 1.189 | H32: 0.67 | I32: 2.111
A36: * = p-value < 0.05
A37: ** = p-value < 0.01

Sheet Odds Ratio Comparisons
A1: HEAD AIS 3+
A2: Effect | B2: Frontal | C2: Oblique (Combined) | D2: Oblique (Left) | E2: Oblique (Right)
A3: log(delta-V mph) | B3: ='Odds Ratios'!B4 -> 11.12 | C3: ='Odds Ratios'!G4 -> 11.413 | D3: ='Odds Ratios'!L4 -> 11.008 | E3: ='Odds Ratios'!Q4 -> 11.01
A4: AGE 36-65 vs 18-35 | B4: ='Odds Ratios'!B5 -> 0.944 | C4: ='Odds Ratios'!G5 -> 1.576 | D4: ='Odds Ratios'!L5 -> 1.089 | E4: ='Odds Ratios'!Q5 -> 3.521
A5: AGE 66+ vs 18-35 | B5: ='Odds Ratios'!B6 -> 1.39 | C5: ='Odds Ratios'!G6 -> 0.909 | D5: ='Odds Ratios'!L6 -> 0.678 | E5: ='Odds Ratios'!Q6 -> 2.624
A6: HEIGHT (per centimeter increase) | B6: ='Odds Ratios'!B7 -> 1.031 | C6: ='Odds Ratios'!G7 -> 1.012 | D6: ='Odds Ratios'!L7 -> 0.987 | E6: ='Odds Ratios'!Q7 -> 1.071
A7: BMI (per unit increase) | B7: ='Odds Ratios'!B8 -> 1.017 | C7: ='Odds Ratios'!G8 -> 1.05 | D7: ='Odds Ratios'!L8 -> 1.061 | E7: ='Odds Ratios'!Q8 -> 1.001
A8: SEX F vs M | B8: ='Odds Ratios'!B9 -> 0.742 | C8: ='Odds Ratios'!G9 -> 0.38 | D8: ='Odds Ratios'!L9 -> 0.287 | E8: ='Odds Ratios'!Q9 -> 0.775
A9: PDOF R vs L | C9: ='Odds Ratios'!G10 -> 0.633
A11: CHEST AIS 3+
A12: Effect | B12: Frontal | C12: Oblique (Combined) | D12: Oblique (Left) | E12: Oblique (Right)
A13: log(delta-V mph) | B13: ='Odds Ratios'!B15 -> 9.414 | C13: ='Odds Ratios'!G15 -> 17.6 | D13: ='Odds Ratios'!L15 -> 12.067 | E13: ='Odds Ratios'!Q15 -> 33.441
A14: AGE 36-65 vs 18-35 | B14: ='Odds Ratios'!B16 -> 4.925 | C14: ='Odds Ratios'!G16 -> 3.577 | D14: ='Odds Ratios'!L16 -> 3.522 | E14: ='Odds Ratios'!Q16 -> 4.055
A15: AGE 66+ vs 18-35 | B15: ='Odds Ratios'!B17 -> 27.27 | C15: ='Odds Ratios'!G17 -> 6.3 | D15: ='Odds Ratios'!L17 -> 1.505 | E15: ='Odds Ratios'!Q17 -> 18.128
A16: HEIGHT (per centimeter increase) | B16: ='Odds Ratios'!B18 -> 1.013 | C16: ='Odds Ratios'!G18 -> 1.02 | D16: ='Odds Ratios'!L18 -> 1.013 | E16: ='Odds Ratios'!Q18 -> 1.031
A17: BMI (per unit increase) | B17: ='Odds Ratios'!B19 -> 1.054 | C17: ='Odds Ratios'!G19 -> 1.001 | D17: ='Odds Ratios'!L19 -> 0.991 | E17: ='Odds Ratios'!Q19 -> 1
A18: SEX F vs M | B18: ='Odds Ratios'!B20 -> 2.549 | C18: ='Odds Ratios'!G20 -> 0.928 | D18: ='Odds Ratios'!L20 -> 0.735 | E18: ='Odds Ratios'!Q20 -> 1.471
A19: PDOF R vs L | C19: ='Odds Ratios'!G21 -> 1.245
A21: LOWER EXTREMITY AIS 2+
A22: Effect | B22: Frontal | C22: Oblique (Combined) | D22: Oblique (Left) | E22: Oblique (Right)
A23: log(delta-V mph) | B23: ='Odds Ratios'!B26 -> 24.939 | C23: ='Odds Ratios'!G26 -> 18.636 | D23: ='Odds Ratios'!L26 -> 12.736 | E23: ='Odds Ratios'!Q26 -> 32.829
A24: AGE 36-65 vs 18-35 | B24: ='Odds Ratios'!B27 -> 1.087 | C24: ='Odds Ratios'!G27 -> 2.033 | D24: ='Odds Ratios'!L27 -> 1.958 | E24: ='Odds Ratios'!Q27 -> 2.119
A25: AGE 66+ vs 18-35 | B25: ='Odds Ratios'!B28 -> 2.504 | C25: ='Odds Ratios'!G28 -> 3.824 | D25: ='Odds Ratios'!L28 -> 2.019 | E25: ='Odds Ratios'!Q28 -> 7.376
A26: HEIGHT (per centimeter increase) | B26: ='Odds Ratios'!B29 -> 0.982 | C26: ='Odds Ratios'!G29 -> 0.98 | D26: ='Odds Ratios'!L29 -> 1 | E26: ='Odds Ratios'!Q29 -> 0.956
A27: BMI (per unit increase) | B27: ='Odds Ratios'!B30 -> 1.071 | C27: ='Odds Ratios'!G30 -> 1.034 | D27: ='Odds Ratios'!L30 -> 1.043 | E27: ='Odds Ratios'!Q30 -> 1.018
A28: SEX F vs M | B28: ='Odds Ratios'!B31 -> 1.274 | C28: ='Odds Ratios'!G31 -> 1.057 | D28: ='Odds Ratios'!L31 -> 1.403 | E28: ='Odds Ratios'!Q31 -> 0.849
A29: PDOF R vs L | C29: ='Odds Ratios'!G32 -> 1.189

Sheet BMI Table
A1: Body Region | B1: LowerExtremity | F1: Estimated Risk of Injury
A2: Direction | B2: Frontal | E2: BMI | F2: Age 18-35 | G2: Age 36-65 | H2: Age 66+
E3: 18 | F3: =1/(1+EXP(-1*(VLOOKUP("Intercept",INDIRECT($B$1&"Coef"),1+MATCH($B$2,ModelTypes,0),FALSE) + VLOOKUP("LDVMPH",INDIRECT($B$1&"Coef"),1+MATCH($B$2,ModelTypes,0),FALSE)*LN($B$5) + VLOOKUP(F$2,INDIRECT($B$1&"Coef"),1+MATCH($B$2,ModelTypes,0),FALSE) + VLOOKUP("Height",INDIRECT($B$1&"Coef"),1+MATCH($B$2,ModelTypes,0),FALSE)*$B$6 + VLOOKUP("BMI",INDIRECT($B$1&"Coef"),1+MATCH($B$2,ModelTypes,0),FALSE)*$E3 + VLOOKUP("Sex "&$B$7,INDIRECT($B$1&"Coef"),1+MATCH($B$2,ModelTypes,0),FALSE)))) -> 0.25576867 | G3: =1/(1+EXP(-1*(VLOOKUP("Intercept",INDIRECT($B$1&"Coef"),1+MATCH($B$2,ModelTypes,0),FALSE) + VLOOKUP("LDVMPH",INDIRECT($B$1&"Coef"),1+MATCH($B$2,ModelTypes,0),FALSE)*LN($B$5) + VLOOKUP(G$2,INDIRECT($B$1&"Coef"),1+MATCH($B$2,ModelTypes,0),FALSE) + VLOOKUP("Height",INDIRECT($B$1&"Coef"),1+MATCH($B$2,ModelTypes,0),FALSE)*$B$6 + VLOOKUP("BMI",INDIRECT($B$1&"Coef"),1+MATCH($B$2,ModelTypes,0),FALSE)*$E3 + VLOOKUP("Sex "&$B$7,INDIRECT($B$1&"Coef"),1+MATCH($B$2,ModelTypes,0),FALSE)))) -> 0.27198426 | H3: =1/(1+EXP(-1*(VLOOKUP("Intercept",INDIRECT($B$1&"Coef"),1+MATCH($B$2,ModelTypes,0),FALSE) + VLOOKUP("LDVMPH",INDIRECT($B$1&"Coef"),1+MATCH($B$2,ModelTypes,0),FALSE)*LN($B$5) + VLOOKUP(H$2,INDIRECT($B$1&"Coef"),1+MATCH($B$2,ModelTypes,0),FALSE) + VLOOKUP("Height",INDIRECT($B$1&"Coef"),1+MATCH($B$2,ModelTypes,0),FALSE)*$B$6 + VLOOKUP("BMI",INDIRECT($B$1&"Coef"),1+MATCH($B$2,ModelTypes,0),FALSE)*$E3 + VLOOKUP("Sex "&$B$7,INDIRECT($B$1&"Coef"),1+MATCH($B$2,ModelTypes,0),FALSE)))) -> 0.46252578
A4: Other Factors | E4: 19 | F4: =1/(1+EXP(-1*(VLOOKUP("Intercept",INDIRECT($B$1&"Coef"),1+MATCH($B$2,ModelTypes,0),FALSE) + VLOOKUP("LDVMPH",INDIRECT($B$1&"Coef"),1+MATCH($B$2,ModelTypes,0),FALSE)*LN($B$5) + VLOOKUP(F$2,INDIRECT($B$1&"Coef"),1+MATCH($B$2,ModelTypes,0),FALSE) + VLOOKUP("Height",INDIRECT($B$1&"Coef"),1+MATCH($B$2,ModelTypes,0),FALSE)*$B$6 + VLOOKUP("BMI",INDIRECT($B$1&"Coef"),1+MATCH($B$2,ModelTypes,0),FALSE)*$E4 + VLOOKUP("Sex "&$B$7,INDIRECT($B$1&"Coef"),1+MATCH($B$2,ModelTypes,0),FALSE)))) -> 0.26910297 | G4: =1/(1+EXP(-1*(VLOOKUP("Intercept",INDIRECT($B$1&"Coef"),1+MATCH($B$2,ModelTypes,0),FALSE) + VLOOKUP("LDVMPH",INDIRECT($B$1&"Coef"),1+MATCH($B$2,ModelTypes,0),FALSE)*LN($B$5) + VLOOKUP(G$2,INDIRECT($B$1&"Coef"),1+MATCH($B$2,ModelTypes,0),FALSE) + VLOOKUP("Height",INDIRECT($B$1&"Coef"),1+MATCH($B$2,ModelTypes,0),FALSE)*$B$6 + VLOOKUP("BMI",INDIRECT($B$1&"Coef"),1+MATCH($B$2,ModelTypes,0),FALSE)*$E4 + VLOOKUP("Sex "&$B$7,INDIRECT($B$1&"Coef"),1+MATCH($B$2,ModelTypes,0),FALSE)))) -> 0.28583925 | H4: =1/(1+EXP(-1*(VLOOKUP("Intercept",INDIRECT($B$1&"Coef"),1+MATCH($B$2,ModelTypes,0),FALSE) + VLOOKUP("LDVMPH",INDIRECT($B$1&"Coef"),1+MATCH($B$2,ModelTypes,0),FALSE)*LN($B$5) + VLOOKUP(H$2,INDIRECT($B$1&"Coef"),1+MATCH($B$2,ModelTypes,0),FALSE) + VLOOKUP("Height",INDIRECT($B$1&"Coef"),1+MATCH($B$2,ModelTypes,0),FALSE)*$B$6 + VLOOKUP("BMI",INDIRECT($B$1&"Coef"),1+MATCH($B$2,ModelTypes,0),FALSE)*$E4 + VLOOKUP("Sex "&$B$7,INDIRECT($B$1&"Coef"),1+MATCH($B$2,ModelTypes,0),FALSE)))) -> 0.47969156
A5: Delta-V (mph) | B5: 35 | E5: 20 | F5: =1/(1+EXP(-1*(VLOOKUP("Intercept",INDIRECT($B$1&"Coef"),1+MATCH($B$2,ModelTypes,0),FALSE) + VLOOKUP("LDVMPH",INDIRECT($B$1&"Coef"),1+MATCH($B$2,ModelTypes,0),FALSE)*LN($B$5) + VLOOKUP(F$2,INDIRECT($B$1&"Coef"),1+MATCH($B$2,ModelTypes,0),FALSE) + VLOOKUP("Height",INDIRECT($B$1&"Coef"),1+MATCH($B$2,ModelTypes,0),FALSE)*$B$6 + VLOOKUP("BMI",INDIRECT($B$1&"Coef"),1+MATCH($B$2,ModelTypes,0),FALSE)*$E5 + VLOOKUP("Sex "&$B$7,INDIRECT($B$1&"Coef"),1+MATCH($B$2,ModelTypes,0),FALSE)))) -> 0.28286822 | G5: =1/(1+EXP(-1*(VLOOKUP("Intercept",INDIRECT($B$1&"Coef"),1+MATCH($B$2,ModelTypes,0),FALSE) + VLOOKUP("LDVMPH",INDIRECT($B$1&"Coef"),1+MATCH($B$2,ModelTypes,0),FALSE)*LN($B$5) + VLOOKUP(G$2,INDIRECT($B$1&"Coef"),1+MATCH($B$2,ModelTypes,0),FALSE) + VLOOKUP("Height",INDIRECT($B$1&"Coef"),1+MATCH($B$2,ModelTypes,0),FALSE)*$B$6 + VLOOKUP("BMI",INDIRECT($B$1&"Coef"),1+MATCH($B$2,ModelTypes,0),FALSE)*$E5 + VLOOKUP("Sex "&$B$7,INDIRECT($B$1&"Coef"),1+MATCH($B$2,ModelTypes,0),FALSE)))) -> 0.30010908 | H5: =1/(1+EXP(-1*(VLOOKUP("Intercept",INDIRECT($B$1&"Coef"),1+MATCH($B$2,ModelTypes,0),FALSE) + VLOOKUP("LDVMPH",INDIRECT($B$1&"Coef"),1+MATCH($B$2,ModelTypes,0),FALSE)*LN($B$5) + VLOOKUP(H$2,INDIRECT($B$1&"Coef"),1+MATCH($B$2,ModelTypes,0),FALSE) + VLOOKUP("Height",INDIRECT($B$1&"Coef"),1+MATCH($B$2,ModelTypes,0),FALSE)*$B$6 + VLOOKUP("BMI",INDIRECT($B$1&"Coef"),1+MATCH($B$2,ModelTypes,0),FALSE)*$E5 + VLOOKUP("Sex "&$B$7,INDIRECT($B$1&"Coef"),1+MATCH($B$2,ModelTypes,0),FALSE)))) -> 0.49690542
A6: Height (cm) | B6: 150 | E6: 21 | F6: =1/(1+EXP(-1*(VLOOKUP("Intercept",INDIRECT($B$1&"Coef"),1+MATCH($B$2,ModelTypes,0),FALSE) + VLOOKUP("LDVMPH",INDIRECT($B$1&"Coef"),1+MATCH($B$2,ModelTypes,0),FALSE)*LN($B$5) + VLOOKUP(F$2,INDIRECT($B$1&"Coef"),1+MATCH($B$2,ModelTypes,0),FALSE) + VLOOKUP("Height",INDIRECT($B$1&"Coef"),1+MATCH($B$2,ModelTypes,0),FALSE)*$B$6 + VLOOKUP("BMI",INDIRECT($B$1&"Coef"),1+MATCH($B$2,ModelTypes,0),FALSE)*$E6 + VLOOKUP("Sex "&$B$7,INDIRECT($B$1&"Coef"),1+MATCH($B$2,ModelTypes,0),FALSE)))) -> 0.29705142 | G6: =1/(1+EXP(-1*(VLOOKUP("Intercept",INDIRECT($B$1&"Coef"),1+MATCH($B$2,ModelTypes,0),FALSE) + VLOOKUP("LDVMPH",INDIRECT($B$1&"Coef"),1+MATCH($B$2,ModelTypes,0),FALSE)*LN($B$5) + VLOOKUP(G$2,INDIRECT($B$1&"Coef"),1+MATCH($B$2,ModelTypes,0),FALSE) + VLOOKUP("Height",INDIRECT($B$1&"Coef"),1+MATCH($B$2,ModelTypes,0),FALSE)*$B$6 + VLOOKUP("BMI",INDIRECT($B$1&"Coef"),1+MATCH($B$2,ModelTypes,0),FALSE)*$E6 + VLOOKUP("Sex "&$B$7,INDIRECT($B$1&"Coef"),1+MATCH($B$2,ModelTypes,0),FALSE)))) -> 0.3147773 | H6: =1/(1+EXP(-1*(VLOOKUP("Intercept",INDIRECT($B$1&"Coef"),1+MATCH($B$2,ModelTypes,0),FALSE) + VLOOKUP("LDVMPH",INDIRECT($B$1&"Coef"),1+MATCH($B$2,ModelTypes,0),FALSE)*LN($B$5) + VLOOKUP(H$2,INDIRECT($B$1&"Coef"),1+MATCH($B$2,ModelTypes,0),FALSE) + VLOOKUP("Height",INDIRECT($B$1&"Coef"),1+MATCH($B$2,ModelTypes,0),FALSE)*$B$6 + VLOOKUP("BMI",INDIRECT($B$1&"Coef"),1+MATCH($B$2,ModelTypes,0),FALSE)*$E6 + VLOOKUP("Sex "&$B$7,INDIRECT($B$1&"Coef"),1+MATCH($B$2,ModelTypes,0),FALSE)))) -> 0.51412662
A7: Sex | B7: F | E7: 22 | F7: =1/(1+EXP(-1*(VLOOKUP("Intercept",INDIRECT($B$1&"Coef"),1+MATCH($B$2,ModelTypes,0),FALSE) + VLOOKUP("LDVMPH",INDIRECT($B$1&"Coef"),1+MATCH($B$2,ModelTypes,0),FALSE)*LN($B$5) + VLOOKUP(F$2,INDIRECT($B$1&"Coef"),1+MATCH($B$2,ModelTypes,0),FALSE) + VLOOKUP("Height",INDIRECT($B$1&"Coef"),1+MATCH($B$2,ModelTypes,0),FALSE)*$B$6 + VLOOKUP("BMI",INDIRECT($B$1&"Coef"),1+MATCH($B$2,ModelTypes,0),FALSE)*$E7 + VLOOKUP("Sex "&$B$7,INDIRECT($B$1&"Coef"),1+MATCH($B$2,ModelTypes,0),FALSE)))) -> 0.31163674 | G7: =1/(1+EXP(-1*(VLOOKUP("Intercept",INDIRECT($B$1&"Coef"),1+MATCH($B$2,ModelTypes,0),FALSE) + VLOOKUP("LDVMPH",INDIRECT($B$1&"Coef"),1+MATCH($B$2,ModelTypes,0),FALSE)*LN($B$5) + VLOOKUP(G$2,INDIRECT($B$1&"Coef"),1+MATCH($B$2,ModelTypes,0),FALSE) + VLOOKUP("Height",INDIRECT($B$1&"Coef"),1+MATCH($B$2,ModelTypes,0),FALSE)*$B$6 + VLOOKUP("BMI",INDIRECT($B$1&"Coef"),1+MATCH($B$2,ModelTypes,0),FALSE)*$E7 + VLOOKUP("Sex "&$B$7,INDIRECT($B$1&"Coef"),1+MATCH($B$2,ModelTypes,0),FALSE)))) -> 0.32982459 | H7: =1/(1+EXP(-1*(VLOOKUP("Intercept",INDIRECT($B$1&"Coef"),1+MATCH($B$2,ModelTypes,0),FALSE) + VLOOKUP("LDVMPH",INDIRECT($B$1&"Coef"),1+MATCH($B$2,ModelTypes,0),FALSE)*LN($B$5) + VLOOKUP(H$2,INDIRECT($B$1&"Coef"),1+MATCH($B$2,ModelTypes,0),FALSE) + VLOOKUP("Height",INDIRECT($B$1&"Coef"),1+MATCH($B$2,ModelTypes,0),FALSE)*$B$6 + VLOOKUP("BMI",INDIRECT($B$1&"Coef"),1+MATCH($B$2,ModelTypes,0),FALSE)*$E7 + VLOOKUP("Sex "&$B$7,INDIRECT($B$1&"Coef"),1+MATCH($B$2,ModelTypes,0),FALSE)))) -> 0.53131434
E8: 23 | F8: =1/(1+EXP(-1*(VLOOKUP("Intercept",INDIRECT($B$1&"Coef"),1+MATCH($B$2,ModelTypes,0),FALSE) + VLOOKUP("LDVMPH",INDIRECT($B$1&"Coef"),1+MATCH($B$2,ModelTypes,0),FALSE)*LN($B$5) + VLOOKUP(F$2,INDIRECT($B$1&"Coef"),1+MATCH($B$2,ModelTypes,0),FALSE) + VLOOKUP("Height",INDIRECT($B$1&"Coef"),1+MATCH($B$2,ModelTypes,0),FALSE)*$B$6 + VLOOKUP("BMI",INDIRECT($B$1&"Coef"),1+MATCH($B$2,ModelTypes,0),FALSE)*$E8 + VLOOKUP("Sex "&$B$7,INDIRECT($B$1&"Coef"),1+MATCH($B$2,ModelTypes,0),FALSE)))) -> 0.32660546 | G8: =1/(1+EXP(-1*(VLOOKUP("Intercept",INDIRECT($B$1&"Coef"),1+MATCH($B$2,ModelTypes,0),FALSE) + VLOOKUP("LDVMPH",INDIRECT($B$1&"Coef"),1+MATCH($B$2,ModelTypes,0),FALSE)*LN($B$5) + VLOOKUP(G$2,INDIRECT($B$1&"Coef"),1+MATCH($B$2,ModelTypes,0),FALSE) + VLOOKUP("Height",INDIRECT($B$1&"Coef"),1+MATCH($B$2,ModelTypes,0),FALSE)*$B$6 + VLOOKUP("BMI",INDIRECT($B$1&"Coef"),1+MATCH($B$2,ModelTypes,0),FALSE)*$E8 + VLOOKUP("Sex "&$B$7,INDIRECT($B$1&"Coef"),1+MATCH($B$2,ModelTypes,0),FALSE)))) -> 0.3452288 | H8: =1/(1+EXP(-1*(VLOOKUP("Intercept",INDIRECT($B$1&"Coef"),1+MATCH($B$2,ModelTypes,0),FALSE) + VLOOKUP("LDVMPH",INDIRECT($B$1&"Coef"),1+MATCH($B$2,ModelTypes,0),FALSE)*LN($B$5) + VLOOKUP(H$2,INDIRECT($B$1&"Coef"),1+MATCH($B$2,ModelTypes,0),FALSE) + VLOOKUP("Height",INDIRECT($B$1&"Coef"),1+MATCH($B$2,ModelTypes,0),FALSE)*$B$6 + VLOOKUP("BMI",INDIRECT($B$1&"Coef"),1+MATCH($B$2,ModelTypes,0),FALSE)*$E8 + VLOOKUP("Sex "&$B$7,INDIRECT($B$1&"Coef"),1+MATCH($B$2,ModelTypes,0),FALSE)))) -> 0.54842808
E9: 24 | F9: =1/(1+EXP(-1*(VLOOKUP("Intercept",INDIRECT($B$1&"Coef"),1+MATCH($B$2,ModelTypes,0),FALSE) + VLOOKUP("LDVMPH",INDIRECT($B$1&"Coef"),1+MATCH($B$2,ModelTypes,0),FALSE)*LN($B$5) + VLOOKUP(F$2,INDIRECT($B$1&"Coef"),1+MATCH($B$2,ModelTypes,0),FALSE) + VLOOKUP("Height",INDIRECT($B$1&"Coef"),1+MATCH($B$2,ModelTypes,0),FALSE)*$B$6 + VLOOKUP("BMI",INDIRECT($B$1&"Coef"),1+MATCH($B$2,ModelTypes,0),FALSE)*$E9 + VLOOKUP("Sex "&$B$7,INDIRECT($B$1&"Coef"),1+MATCH($B$2,ModelTypes,0),FALSE)))) -> 0.34193602 | G9: =1/(1+EXP(-1*(VLOOKUP("Intercept",INDIRECT($B$1&"Coef"),1+MATCH($B$2,ModelTypes,0),FALSE) + VLOOKUP("LDVMPH",INDIRECT($B$1&"Coef"),1+MATCH($B$2,ModelTypes,0),FALSE)*LN($B$5) + VLOOKUP(G$2,INDIRECT($B$1&"Coef"),1+MATCH($B$2,ModelTypes,0),FALSE) + VLOOKUP("Height",INDIRECT($B$1&"Coef"),1+MATCH($B$2,ModelTypes,0),FALSE)*$B$6 + VLOOKUP("BMI",INDIRECT($B$1&"Coef"),1+MATCH($B$2,ModelTypes,0),FALSE)*$E9 + VLOOKUP("Sex "&$B$7,INDIRECT($B$1&"Coef"),1+MATCH($B$2,ModelTypes,0),FALSE)))) -> 0.36096494 | H9: =1/(1+EXP(-1*(VLOOKUP("Intercept",INDIRECT($B$1&"Coef"),1+MATCH($B$2,ModelTypes,0),FALSE) + VLOOKUP("LDVMPH",INDIRECT($B$1&"Coef"),1+MATCH($B$2,ModelTypes,0),FALSE)*LN($B$5) + VLOOKUP(H$2,INDIRECT($B$1&"Coef"),1+MATCH($B$2,ModelTypes,0),FALSE) + VLOOKUP("Height",INDIRECT($B$1&"Coef"),1+MATCH($B$2,ModelTypes,0),FALSE)*$B$6 + VLOOKUP("BMI",INDIRECT($B$1&"Coef"),1+MATCH($B$2,ModelTypes,0),FALSE)*$E9 + VLOOKUP("Sex "&$B$7,INDIRECT($B$1&"Coef"),1+MATCH($B$2,ModelTypes,0),FALSE)))) -> 0.56542804
E10: 25 | F10: =1/(1+EXP(-1*(VLOOKUP("Intercept",INDIRECT($B$1&"Coef"),1+MATCH($B$2,ModelTypes,0),FALSE) + VLOOKUP("LDVMPH",INDIRECT($B$1&"Coef"),1+MATCH($B$2,ModelTypes,0),FALSE)*LN($B$5) + VLOOKUP(F$2,INDIRECT($B$1&"Coef"),1+MATCH($B$2,ModelTypes,0),FALSE) + VLOOKUP("Height",INDIRECT($B$1&"Coef"),1+MATCH($B$2,ModelTypes,0),FALSE)*$B$6 + VLOOKUP("BMI",INDIRECT($B$1&"Coef"),1+MATCH($B$2,ModelTypes,0),FALSE)*$E10 + VLOOKUP("Sex "&$B$7,INDIRECT($B$1&"Coef"),1+MATCH($B$2,ModelTypes,0),FALSE)))) -> 0.35760405 | G10: =1/(1+EXP(-1*(VLOOKUP("Intercept",INDIRECT($B$1&"Coef"),1+MATCH($B$2,ModelTypes,0),FALSE) + VLOOKUP("LDVMPH",INDIRECT($B$1&"Coef"),1+MATCH($B$2,ModelTypes,0),FALSE)*LN($B$5) + VLOOKUP(G$2,INDIRECT($B$1&"Coef"),1+MATCH($B$2,ModelTypes,0),FALSE) + VLOOKUP("Height",INDIRECT($B$1&"Coef"),1+MATCH($B$2,ModelTypes,0),FALSE)*$B$6 + VLOOKUP("BMI",INDIRECT($B$1&"Coef"),1+MATCH($B$2,ModelTypes,0),FALSE)*$E10 + VLOOKUP("Sex "&$B$7,INDIRECT($B$1&"Coef"),1+MATCH($B$2,ModelTypes,0),FALSE)))) -> 0.37700536 | H10: =1/(1+EXP(-1*(VLOOKUP("Intercept",INDIRECT($B$1&"Coef"),1+MATCH($B$2,ModelTypes,0),FALSE) + VLOOKUP("LDVMPH",INDIRECT($B$1&"Coef"),1+MATCH($B$2,ModelTypes,0),FALSE)*LN($B$5) + VLOOKUP(H$2,INDIRECT($B$1&"Coef"),1+MATCH($B$2,ModelTypes,0),FALSE) + VLOOKUP("Height",INDIRECT($B$1&"Coef"),1+MATCH($B$2,ModelTypes,0),FALSE)*$B$6 + VLOOKUP("BMI",INDIRECT($B$1&"Coef"),1+MATCH($B$2,ModelTypes,0),FALSE)*$E10 + VLOOKUP("Sex "&$B$7,INDIRECT($B$1&"Coef"),1+MATCH($B$2,ModelTypes,0),FALSE)))) -> 0.58227548
E11: 26 | F11: =1/(1+EXP(-1*(VLOOKUP("Intercept",INDIRECT($B$1&"Coef"),1+MATCH($B$2,ModelTypes,0),FALSE) + VLOOKUP("LDVMPH",INDIRECT($B$1&"Coef"),1+MATCH($B$2,ModelTypes,0),FALSE)*LN($B$5) + VLOOKUP(F$2,INDIRECT($B$1&"Coef"),1+MATCH($B$2,ModelTypes,0),FALSE) + VLOOKUP("Height",INDIRECT($B$1&"Coef"),1+MATCH($B$2,ModelTypes,0),FALSE)*$B$6 + VLOOKUP("BMI",INDIRECT($B$1&"Coef"),1+MATCH($B$2,ModelTypes,0),FALSE)*$E11 + VLOOKUP("Sex "&$B$7,INDIRECT($B$1&"Coef"),1+MATCH($B$2,ModelTypes,0),FALSE)))) -> 0.37358244 | G11: =1/(1+EXP(-1*(VLOOKUP("Intercept",INDIRECT($B$1&"Coef"),1+MATCH($B$2,ModelTypes,0),FALSE) + VLOOKUP("LDVMPH",INDIRECT($B$1&"Coef"),1+MATCH($B$2,ModelTypes,0),FALSE)*LN($B$5) + VLOOKUP(G$2,INDIRECT($B$1&"Coef"),1+MATCH($B$2,ModelTypes,0),FALSE) + VLOOKUP("Height",INDIRECT($B$1&"Coef"),1+MATCH($B$2,ModelTypes,0),FALSE)*$B$6 + VLOOKUP("BMI",INDIRECT($B$1&"Coef"),1+MATCH($B$2,ModelTypes,0),FALSE)*$E11 + VLOOKUP("Sex "&$B$7,INDIRECT($B$1&"Coef"),1+MATCH($B$2,ModelTypes,0),FALSE)))) -> 0.39331987 | H11: =1/(1+EXP(-1*(VLOOKUP("Intercept",INDIRECT($B$1&"Coef"),1+MATCH($B$2,ModelTypes,0),FALSE) + VLOOKUP("LDVMPH",INDIRECT($B$1&"Coef"),1+MATCH($B$2,ModelTypes,0),FALSE)*LN($B$5) + VLOOKUP(H$2,INDIRECT($B$1&"Coef"),1+MATCH($B$2,ModelTypes,0),FALSE) + VLOOKUP("Height",INDIRECT($B$1&"Coef"),1+MATCH($B$2,ModelTypes,0),FALSE)*$B$6 + VLOOKUP("BMI",INDIRECT($B$1&"Coef"),1+MATCH($B$2,ModelTypes,0),FALSE)*$E11 + VLOOKUP("Sex "&$B$7,INDIRECT($B$1&"Coef"),1+MATCH($B$2,ModelTypes,0),FALSE)))) -> 0.59893306
E12: 27 | F12: =1/(1+EXP(-1*(VLOOKUP("Intercept",INDIRECT($B$1&"Coef"),1+MATCH($B$2,ModelTypes,0),FALSE) + VLOOKUP("LDVMPH",INDIRECT($B$1&"Coef"),1+MATCH($B$2,ModelTypes,0),FALSE)*LN($B$5) + VLOOKUP(F$2,INDIRECT($B$1&"Coef"),1+MATCH($B$2,ModelTypes,0),FALSE) + VLOOKUP("Height",INDIRECT($B$1&"Coef"),1+MATCH($B$2,ModelTypes,0),FALSE)*$B$6 + VLOOKUP("BMI",INDIRECT($B$1&"Coef"),1+MATCH($B$2,ModelTypes,0),FALSE)*$E12 + VLOOKUP("Sex "&$B$7,INDIRECT($B$1&"Coef"),1+MATCH($B$2,ModelTypes,0),FALSE)))) -> 0.3898415 | G12: =1/(1+EXP(-1*(VLOOKUP("Intercept",INDIRECT($B$1&"Coef"),1+MATCH($B$2,ModelTypes,0),FALSE) + VLOOKUP("LDVMPH",INDIRECT($B$1&"Coef"),1+MATCH($B$2,ModelTypes,0),FALSE)*LN($B$5) + VLOOKUP(G$2,INDIRECT($B$1&"Coef"),1+MATCH($B$2,ModelTypes,0),FALSE) + VLOOKUP("Height",INDIRECT($B$1&"Coef"),1+MATCH($B$2,ModelTypes,0),FALSE)*$B$6 + VLOOKUP("BMI",INDIRECT($B$1&"Coef"),1+MATCH($B$2,ModelTypes,0),FALSE)*$E12 + VLOOKUP("Sex "&$B$7,INDIRECT($B$1&"Coef"),1+MATCH($B$2,ModelTypes,0),FALSE)))) -> 0.40987588 | H12: =1/(1+EXP(-1*(VLOOKUP("Intercept",INDIRECT($B$1&"Coef"),1+MATCH($B$2,ModelTypes,0),FALSE) + VLOOKUP("LDVMPH",INDIRECT($B$1&"Coef"),1+MATCH($B$2,ModelTypes,0),FALSE)*LN($B$5) + VLOOKUP(H$2,INDIRECT($B$1&"Coef"),1+MATCH($B$2,ModelTypes,0),FALSE) + VLOOKUP("Height",INDIRECT($B$1&"Coef"),1+MATCH($B$2,ModelTypes,0),FALSE)*$B$6 + VLOOKUP("BMI",INDIRECT($B$1&"Coef"),1+MATCH($B$2,ModelTypes,0),FALSE)*$E12 + VLOOKUP("Sex "&$B$7,INDIRECT($B$1&"Coef"),1+MATCH($B$2,ModelTypes,0),FALSE)))) -> 0.61536518
E13: 28 | F13: =1/(1+EXP(-1*(VLOOKUP("Intercept",INDIRECT($B$1&"Coef"),1+MATCH($B$2,ModelTypes,0),FALSE) + VLOOKUP("LDVMPH",INDIRECT($B$1&"Coef"),1+MATCH($B$2,ModelTypes,0),FALSE)*LN($B$5) + VLOOKUP(F$2,INDIRECT($B$1&"Coef"),1+MATCH($B$2,ModelTypes,0),FALSE) + VLOOKUP("Height",INDIRECT($B$1&"Coef"),1+MATCH($B$2,ModelTypes,0),FALSE)*$B$6 + VLOOKUP("BMI",INDIRECT($B$1&"Coef"),1+MATCH($B$2,ModelTypes,0),FALSE)*$E13 + VLOOKUP("Sex "&$B$7,INDIRECT($B$1&"Coef"),1+MATCH($B$2,ModelTypes,0),FALSE)))) -> 0.40634917 | G13: =1/(1+EXP(-1*(VLOOKUP("Intercept",INDIRECT($B$1&"Coef"),1+MATCH($B$2,ModelTypes,0),FALSE) + VLOOKUP("LDVMPH",INDIRECT($B$1&"Coef"),1+MATCH($B$2,ModelTypes,0),FALSE)*LN($B$5) + VLOOKUP(G$2,INDIRECT($B$1&"Coef"),1+MATCH($B$2,ModelTypes,0),FALSE) + VLOOKUP("Height",INDIRECT($B$1&"Coef"),1+MATCH($B$2,ModelTypes,0),FALSE)*$B$6 + VLOOKUP("BMI",INDIRECT($B$1&"Coef"),1+MATCH($B$2,ModelTypes,0),FALSE)*$E13 + VLOOKUP("Sex "&$B$7,INDIRECT($B$1&"Coef"),1+MATCH($B$2,ModelTypes,0),FALSE)))) -> 0.42663871 | H13: =1/(1+EXP(-1*(VLOOKUP("Intercept",INDIRECT($B$1&"Coef"),1+MATCH($B$2,ModelTypes,0),FALSE) + VLOOKUP("LDVMPH",INDIRECT($B$1&"Coef"),1+MATCH($B$2,ModelTypes,0),FALSE)*LN($B$5) + VLOOKUP(H$2,INDIRECT($B$1&"Coef"),1+MATCH($B$2,ModelTypes,0),FALSE) + VLOOKUP("Height",INDIRECT($B$1&"Coef"),1+MATCH($B$2,ModelTypes,0),FALSE)*$B$6 + VLOOKUP("BMI",INDIRECT($B$1&"Coef"),1+MATCH($B$2,ModelTypes,0),FALSE)*$E13 + VLOOKUP("Sex "&$B$7,INDIRECT($B$1&"Coef"),1+MATCH($B$2,ModelTypes,0),FALSE)))) -> 0.63153823
E14: 29 | F14: =1/(1+EXP(-1*(VLOOKUP("Intercept",INDIRECT($B$1&"Coef"),1+MATCH($B$2,ModelTypes,0),FALSE) + VLOOKUP("LDVMPH",INDIRECT($B$1&"Coef"),1+MATCH($B$2,ModelTypes,0),FALSE)*LN($B$5) + VLOOKUP(F$2,INDIRECT($B$1&"Coef"),1+MATCH($B$2,ModelTypes,0),FALSE) + VLOOKUP("Height",INDIRECT($B$1&"Coef"),1+MATCH($B$2,ModelTypes,0),FALSE)*$B$6 + VLOOKUP("BMI",INDIRECT($B$1&"Coef"),1+MATCH($B$2,ModelTypes,0),FALSE)*$E14 + VLOOKUP("Sex "&$B$7,INDIRECT($B$1&"Coef"),1+MATCH($B$2,ModelTypes,0),FALSE)))) -> 0.42307117 | G14: =1/(1+EXP(-1*(VLOOKUP("Intercept",INDIRECT($B$1&"Coef"),1+MATCH($B$2,ModelTypes,0),FALSE) + VLOOKUP("LDVMPH",INDIRECT($B$1&"Coef"),1+MATCH($B$2,ModelTypes,0),FALSE)*LN($B$5) + VLOOKUP(G$2,INDIRECT($B$1&"Coef"),1+MATCH($B$2,ModelTypes,0),FALSE) + VLOOKUP("Height",INDIRECT($B$1&"Coef"),1+MATCH($B$2,ModelTypes,0),FALSE)*$B$6 + VLOOKUP("BMI",INDIRECT($B$1&"Coef"),1+MATCH($B$2,ModelTypes,0),FALSE)*$E14 + VLOOKUP("Sex "&$B$7,INDIRECT($B$1&"Coef"),1+MATCH($B$2,ModelTypes,0),FALSE)))) -> 0.44357179 | H14: =1/(1+EXP(-1*(VLOOKUP("Intercept",INDIRECT($B$1&"Coef"),1+MATCH($B$2,ModelTypes,0),FALSE) + VLOOKUP("LDVMPH",INDIRECT($B$1&"Coef"),1+MATCH($B$2,ModelTypes,0),FALSE)*LN($B$5) + VLOOKUP(H$2,INDIRECT($B$1&"Coef"),1+MATCH($B$2,ModelTypes,0),FALSE) + VLOOKUP("Height",INDIRECT($B$1&"Coef"),1+MATCH($B$2,ModelTypes,0),FALSE)*$B$6 + VLOOKUP("BMI",INDIRECT($B$1&"Coef"),1+MATCH($B$2,ModelTypes,0),FALSE)*$E14 + VLOOKUP("Sex "&$B$7,INDIRECT($B$1&"Coef"),1+MATCH($B$2,ModelTypes,0),FALSE)))) -> 0.64742087
E15: 30 | F15: =1/(1+EXP(-1*(VLOOKUP("Intercept",INDIRECT($B$1&"Coef"),1+MATCH($B$2,ModelTypes,0),FALSE) + VLOOKUP("LDVMPH",INDIRECT($B$1&"Coef"),1+MATCH($B$2,ModelTypes,0),FALSE)*LN($B$5) + VLOOKUP(F$2,INDIRECT($B$1&"Coef"),1+MATCH($B$2,ModelTypes,0),FALSE) + VLOOKUP("Height",INDIRECT($B$1&"Coef"),1+MATCH($B$2,ModelTypes,0),FALSE)*$B$6 + VLOOKUP("BMI",INDIRECT($B$1&"Coef"),1+MATCH($B$2,ModelTypes,0),FALSE)*$E15 + VLOOKUP("Sex "&$B$7,INDIRECT($B$1&"Coef"),1+MATCH($B$2,ModelTypes,0),FALSE)))) -> 0.43997131 | G15: =1/(1+EXP(-1*(VLOOKUP("Intercept",INDIRECT($B$1&"Coef"),1+MATCH($B$2,ModelTypes,0),FALSE) + VLOOKUP("LDVMPH",INDIRECT($B$1&"Coef"),1+MATCH($B$2,ModelTypes,0),FALSE)*LN($B$5) + VLOOKUP(G$2,INDIRECT($B$1&"Coef"),1+MATCH($B$2,ModelTypes,0),FALSE) + VLOOKUP("Height",INDIRECT($B$1&"Coef"),1+MATCH($B$2,ModelTypes,0),FALSE)*$B$6 + VLOOKUP("BMI",INDIRECT($B$1&"Coef"),1+MATCH($B$2,ModelTypes,0),FALSE)*$E15 + VLOOKUP("Sex "&$B$7,INDIRECT($B$1&"Coef"),1+MATCH($B$2,ModelTypes,0),FALSE)))) -> 0.460637 | H15: =1/(1+EXP(-1*(VLOOKUP("Intercept",INDIRECT($B$1&"Coef"),1+MATCH($B$2,ModelTypes,0),FALSE) + VLOOKUP("LDVMPH",INDIRECT($B$1&"Coef"),1+MATCH($B$2,ModelTypes,0),FALSE)*LN($B$5) + VLOOKUP(H$2,INDIRECT($B$1&"Coef"),1+MATCH($B$2,ModelTypes,0),FALSE) + VLOOKUP("Height",INDIRECT($B$1&"Coef"),1+MATCH($B$2,ModelTypes,0),FALSE)*$B$6 + VLOOKUP("BMI",INDIRECT($B$1&"Coef"),1+MATCH($B$2,ModelTypes,0),FALSE)*$E15 + VLOOKUP("Sex "&$B$7,INDIRECT($B$1&"Coef"),1+MATCH($B$2,ModelTypes,0),FALSE)))) -> 0.66298424
E16: 31 | F16: =1/(1+EXP(-1*(VLOOKUP("Intercept",INDIRECT($B$1&"Coef"),1+MATCH($B$2,ModelTypes,0),FALSE) + VLOOKUP("LDVMPH",INDIRECT($B$1&"Coef"),1+MATCH($B$2,ModelTypes,0),FALSE)*LN($B$5) + VLOOKUP(F$2,INDIRECT($B$1&"Coef"),1+MATCH($B$2,ModelTypes,0),FALSE) + VLOOKUP("Height",INDIRECT($B$1&"Coef"),1+MATCH($B$2,ModelTypes,0),FALSE)*$B$6 + VLOOKUP("BMI",INDIRECT($B$1&"Coef"),1+MATCH($B$2,ModelTypes,0),FALSE)*$E16 + VLOOKUP("Sex "&$B$7,INDIRECT($B$1&"Coef"),1+MATCH($B$2,ModelTypes,0),FALSE)))) -> 0.45701177 | G16: =1/(1+EXP(-1*(VLOOKUP("Intercept",INDIRECT($B$1&"Coef"),1+MATCH($B$2,ModelTypes,0),FALSE) + VLOOKUP("LDVMPH",INDIRECT($B$1&"Coef"),1+MATCH($B$2,ModelTypes,0),FALSE)*LN($B$5) + VLOOKUP(G$2,INDIRECT($B$1&"Coef"),1+MATCH($B$2,ModelTypes,0),FALSE) + VLOOKUP("Height",INDIRECT($B$1&"Coef"),1+MATCH($B$2,ModelTypes,0),FALSE)*$B$6 + VLOOKUP("BMI",INDIRECT($B$1&"Coef"),1+MATCH($B$2,ModelTypes,0),FALSE)*$E16 + VLOOKUP("Sex "&$B$7,INDIRECT($B$1&"Coef"),1+MATCH($B$2,ModelTypes,0),FALSE)))) -> 0.47779499 | H16: =1/(1+EXP(-1*(VLOOKUP("Intercept",INDIRECT($B$1&"Coef"),1+MATCH($B$2,ModelTypes,0),FALSE) + VLOOKUP("LDVMPH",INDIRECT($B$1&"Coef"),1+MATCH($B$2,ModelTypes,0),FALSE)*LN($B$5) + VLOOKUP(H$2,INDIRECT($B$1&"Coef"),1+MATCH($B$2,ModelTypes,0),FALSE) + VLOOKUP("Height",INDIRECT($B$1&"Coef"),1+MATCH($B$2,ModelTypes,0),FALSE)*$B$6 + VLOOKUP("BMI",INDIRECT($B$1&"Coef"),1+MATCH($B$2,ModelTypes,0),FALSE)*$E16 + VLOOKUP("Sex "&$B$7,INDIRECT($B$1&"Coef"),1+MATCH($B$2,ModelTypes,0),FALSE)))) -> 0.67820208
E17: 32 | F17: =1/(1+EXP(-1*(VLOOKUP("Intercept",INDIRECT($B$1&"Coef"),1+MATCH($B$2,ModelTypes,0),FALSE) + VLOOKUP("LDVMPH",INDIRECT($B$1&"Coef"),1+MATCH($B$2,ModelTypes,0),FALSE)*LN($B$5) + VLOOKUP(F$2,INDIRECT($B$1&"Coef"),1+MATCH($B$2,ModelTypes,0),FALSE) + VLOOKUP("Height",INDIRECT($B$1&"Coef"),1+MATCH($B$2,ModelTypes,0),FALSE)*$B$6 + VLOOKUP("BMI",INDIRECT($B$1&"Coef"),1+MATCH($B$2,ModelTypes,0),FALSE)*$E17 + VLOOKUP("Sex "&$B$7,INDIRECT($B$1&"Coef"),1+MATCH($B$2,ModelTypes,0),FALSE)))) -> 0.47415344 | G17: =1/(1+EXP(-1*(VLOOKUP("Intercept",INDIRECT($B$1&"Coef"),1+MATCH($B$2,ModelTypes,0),FALSE) + VLOOKUP("LDVMPH",INDIRECT($B$1&"Coef"),1+MATCH($B$2,ModelTypes,0),FALSE)*LN($B$5) + VLOOKUP(G$2,INDIRECT($B$1&"Coef"),1+MATCH($B$2,ModelTypes,0),FALSE) + VLOOKUP("Height",INDIRECT($B$1&"Coef"),1+MATCH($B$2,ModelTypes,0),FALSE)*$B$6 + VLOOKUP("BMI",INDIRECT($B$1&"Coef"),1+MATCH($B$2,ModelTypes,0),FALSE)*$E17 + VLOOKUP("Sex "&$B$7,INDIRECT($B$1&"Coef"),1+MATCH($B$2,ModelTypes,0),FALSE)))) -> 0.49500554 | H17: =1/(1+EXP(-1*(VLOOKUP("Intercept",INDIRECT($B$1&"Coef"),1+MATCH($B$2,ModelTypes,0),FALSE) + VLOOKUP("LDVMPH",INDIRECT($B$1&"Coef"),1+MATCH($B$2,ModelTypes,0),FALSE)*LN($B$5) + VLOOKUP(H$2,INDIRECT($B$1&"Coef"),1+MATCH($B$2,ModelTypes,0),FALSE) + VLOOKUP("Height",INDIRECT($B$1&"Coef"),1+MATCH($B$2,ModelTypes,0),FALSE)*$B$6 + VLOOKUP("BMI",INDIRECT($B$1&"Coef"),1+MATCH($B$2,ModelTypes,0),FALSE)*$E17 + VLOOKUP("Sex "&$B$7,INDIRECT($B$1&"Coef"),1+MATCH($B$2,ModelTypes,0),FALSE)))) -> 0.6930509
E18: 33 | F18: =1/(1+EXP(-1*(VLOOKUP("Intercept",INDIRECT($B$1&"Coef"),1+MATCH($B$2,ModelTypes,0),FALSE) + VLOOKUP("LDVMPH",INDIRECT($B$1&"Coef"),1+MATCH($B$2,ModelTypes,0),FALSE)*LN($B$5) + VLOOKUP(F$2,INDIRECT($B$1&"Coef"),1+MATCH($B$2,ModelTypes,0),FALSE) + VLOOKUP("Height",INDIRECT($B$1&"Coef"),1+MATCH($B$2,ModelTypes,0),FALSE)*$B$6 + VLOOKUP("BMI",INDIRECT($B$1&"Coef"),1+MATCH($B$2,ModelTypes,0),FALSE)*$E18 + VLOOKUP("Sex "&$B$7,INDIRECT($B$1&"Coef"),1+MATCH($B$2,ModelTypes,0),FALSE)))) -> 0.49135624 | G18: =1/(1+EXP(-1*(VLOOKUP("Intercept",INDIRECT($B$1&"Coef"),1+MATCH($B$2,ModelTypes,0),FALSE) + VLOOKUP("LDVMPH",INDIRECT($B$1&"Coef"),1+MATCH($B$2,ModelTypes,0),FALSE)*LN($B$5) + VLOOKUP(G$2,INDIRECT($B$1&"Coef"),1+MATCH($B$2,ModelTypes,0),FALSE) + VLOOKUP("Height",INDIRECT($B$1&"Coef"),1+MATCH($B$2,ModelTypes,0),FALSE)*$B$6 + VLOOKUP("BMI",INDIRECT($B$1&"Coef"),1+MATCH($B$2,ModelTypes,0),FALSE)*$E18 + VLOOKUP("Sex "&$B$7,INDIRECT($B$1&"Coef"),1+MATCH($B$2,ModelTypes,0),FALSE)))) -> 0.51222794 | H18: =1/(1+EXP(-1*(VLOOKUP("Intercept",INDIRECT($B$1&"Coef"),1+MATCH($B$2,ModelTypes,0),FALSE) + VLOOKUP("LDVMPH",INDIRECT($B$1&"Coef"),1+MATCH($B$2,ModelTypes,0),FALSE)*LN($B$5) + VLOOKUP(H$2,INDIRECT($B$1&"Coef"),1+MATCH($B$2,ModelTypes,0),FALSE) + VLOOKUP("Height",INDIRECT($B$1&"Coef"),1+MATCH($B$2,ModelTypes,0),FALSE)*$B$6 + VLOOKUP("BMI",INDIRECT($B$1&"Coef"),1+MATCH($B$2,ModelTypes,0),FALSE)*$E18 + VLOOKUP("Sex "&$B$7,INDIRECT($B$1&"Coef"),1+MATCH($B$2,ModelTypes,0),FALSE)))) -> 0.70751005
E19: 34 | F19: =1/(1+EXP(-1*(VLOOKUP("Intercept",INDIRECT($B$1&"Coef"),1+MATCH($B$2,ModelTypes,0),FALSE) + VLOOKUP("LDVMPH",INDIRECT($B$1&"Coef"),1+MATCH($B$2,ModelTypes,0),FALSE)*LN($B$5) + VLOOKUP(F$2,INDIRECT($B$1&"Coef"),1+MATCH($B$2,ModelTypes,0),FALSE) + VLOOKUP("Height",INDIRECT($B$1&"Coef"),1+MATCH($B$2,ModelTypes,0),FALSE)*$B$6 + VLOOKUP("BMI",INDIRECT($B$1&"Coef"),1+MATCH($B$2,ModelTypes,0),FALSE)*$E19 + VLOOKUP("Sex "&$B$7,INDIRECT($B$1&"Coef"),1+MATCH($B$2,ModelTypes,0),FALSE)))) -> 0.50857953 | G19: =1/(1+EXP(-1*(VLOOKUP("Intercept",INDIRECT($B$1&"Coef"),1+MATCH($B$2,ModelTypes,0),FALSE) + VLOOKUP("LDVMPH",INDIRECT($B$1&"Coef"),1+MATCH($B$2,ModelTypes,0),FALSE)*LN($B$5) + VLOOKUP(G$2,INDIRECT($B$1&"Coef"),1+MATCH($B$2,ModelTypes,0),FALSE) + VLOOKUP("Height",INDIRECT($B$1&"Coef"),1+MATCH($B$2,ModelTypes,0),FALSE)*$B$6 + VLOOKUP("BMI",INDIRECT($B$1&"Coef"),1+MATCH($B$2,ModelTypes,0),FALSE)*$E19 + VLOOKUP("Sex "&$B$7,INDIRECT($B$1&"Coef"),1+MATCH($B$2,ModelTypes,0),FALSE)))) -> 0.52942135 | H19: =1/(1+EXP(-1*(VLOOKUP("Intercept",INDIRECT($B$1&"Coef"),1+MATCH($B$2,ModelTypes,0),FALSE) + VLOOKUP("LDVMPH",INDIRECT($B$1&"Coef"),1+MATCH($B$2,ModelTypes,0),FALSE)*LN($B$5) + VLOOKUP(H$2,INDIRECT($B$1&"Coef"),1+MATCH($B$2,ModelTypes,0),FALSE) + VLOOKUP("Height",INDIRECT($B$1&"Coef"),1+MATCH($B$2,ModelTypes,0),FALSE)*$B$6 + VLOOKUP("BMI",INDIRECT($B$1&"Coef"),1+MATCH($B$2,ModelTypes,0),FALSE)*$E19 + VLOOKUP("Sex "&$B$7,INDIRECT($B$1&"Coef"),1+MATCH($B$2,ModelTypes,0),FALSE)))) -> 0.72156172
... E30: 45 | F30: =1/(1+EXP(-1*(VLOOKUP("Intercept",INDIRECT($B$1&"Coef"),1+MATCH($B$2,ModelTypes,0),FALSE) + VLOOKUP("LDVMPH",INDIRECT($B$1&"Coef"),1+MATCH($B$2,ModelTypes,0),FALSE)*LN($B$5) + VLOOKUP(F$2,INDIRECT($B$1&"Coef"),1+MATCH($B$2,ModelTypes,0),FALSE) + VLOOKUP("Height",INDIRECT($B$1&"Coef"),1+MATCH($B$2,ModelTypes,0),FALSE)*$B$6 + VLOOKUP("BMI",INDIRECT($B$1&"Coef"),1+MATCH($B$2,ModelTypes,0),FALSE)*$E30 + VLOOKUP("Sex "&$B$7,INDIRECT($B$1&"Coef"),1+MATCH($B$2,ModelTypes,0),FALSE)))) -> 0.68830813 | G30: =1/(1+EXP(-1*(VLOOKUP("Intercept",INDIRECT($B$1&"Coef"),1+MATCH($B$2,ModelTypes,0),FALSE) + VLOOKUP("LDVMPH",INDIRECT($B$1&"Coef"),1+MATCH($B$2,ModelTypes,0),FALSE)*LN($B$5) + VLOOKUP(G$2,INDIRECT($B$1&"Coef"),1+MATCH($B$2,ModelTypes,0),FALSE) + VLOOKUP("Height",INDIRECT($B$1&"Coef"),1+MATCH($B$2,ModelTypes,0),FALSE)*$B$6 + VLOOKUP("BMI",INDIRECT($B$1&"Coef"),1+MATCH($B$2,ModelTypes,0),FALSE)*$E30 + VLOOKUP("Sex "&$B$7,INDIRECT($B$1&"Coef"),1+MATCH($B$2,ModelTypes,0),FALSE)))) -> 0.70593483 | H30: =1/(1+EXP(-1*(VLOOKUP("Intercept",INDIRECT($B$1&"Coef"),1+MATCH($B$2,ModelTypes,0),FALSE) + VLOOKUP("LDVMPH",INDIRECT($B$1&"Coef"),1+MATCH($B$2,ModelTypes,0),FALSE)*LN($B$5) + VLOOKUP(H$2,INDIRECT($B$1&"Coef"),1+MATCH($B$2,ModelTypes,0),FALSE) + VLOOKUP("Height",INDIRECT($B$1&"Coef"),1+MATCH($B$2,ModelTypes,0),FALSE)*$B$6 + VLOOKUP("BMI",INDIRECT($B$1&"Coef"),1+MATCH($B$2,ModelTypes,0),FALSE)*$E30 + VLOOKUP("Sex "&$B$7,INDIRECT($B$1&"Coef"),1+MATCH($B$2,ModelTypes,0),FALSE)))) -> 0.84685204

Sheet Height Table
A1: Body Region | B1: Head | F1: Estimated Risk of Injury
A2: Direction | B2: Frontal | E2: Height | F2: Age 18-35 | G2: Age 36-65 | H2: Age 66+
E3: 120 | F3: =1/(1+EXP(-1*(VLOOKUP("Intercept",INDIRECT($B$1&"Coef"),1+MATCH($B$2,ModelTypes,0),FALSE) + VLOOKUP("LDVMPH",INDIRECT($B$1&"Coef"),1+MATCH($B$2,ModelTypes,0),FALSE)*LN($B$5) + VLOOKUP(F$2,INDIRECT($B$1&"Coef"),1+MATCH($B$2,ModelTypes,0),FALSE) + VLOOKUP("Height",INDIRECT($B$1&"Coef"),1+MATCH($B$2,ModelTypes,0),FALSE)*$E3 + VLOOKUP("BMI",INDIRECT($B$1&"Coef"),1+MATCH($B$2,ModelTypes,0),FALSE)*$B$6 + VLOOKUP("Sex "&$B$7,INDIRECT($B$1&"Coef"),1+MATCH($B$2,ModelTypes,0),FALSE)))) -> 0.0058509821 | G3: =1/(1+EXP(-1*(VLOOKUP("Intercept",INDIRECT($B$1&"Coef"),1+MATCH($B$2,ModelTypes,0),FALSE) + VLOOKUP("LDVMPH",INDIRECT($B$1&"Coef"),1+MATCH($B$2,ModelTypes,0),FALSE)*LN($B$5) + VLOOKUP(G$2,INDIRECT($B$1&"Coef"),1+MATCH($B$2,ModelTypes,0),FALSE) + VLOOKUP("Height",INDIRECT($B$1&"Coef"),1+MATCH($B$2,ModelTypes,0),FALSE)*$E3 + VLOOKUP("BMI",INDIRECT($B$1&"Coef"),1+MATCH($B$2,ModelTypes,0),FALSE)*$B$6 + VLOOKUP("Sex "&$B$7,INDIRECT($B$1&"Coef"),1+MATCH($B$2,ModelTypes,0),FALSE)))) -> 0.0055258469 | H3: =1/(1+EXP(-1*(VLOOKUP("Intercept",INDIRECT($B$1&"Coef"),1+MATCH($B$2,ModelTypes,0),FALSE) + VLOOKUP("LDVMPH",INDIRECT($B$1&"Coef"),1+MATCH($B$2,ModelTypes,0),FALSE)*LN($B$5) + VLOOKUP(H$2,INDIRECT($B$1&"Coef"),1+MATCH($B$2,ModelTypes,0),FALSE) + VLOOKUP("Height",INDIRECT($B$1&"Coef"),1+MATCH($B$2,ModelTypes,0),FALSE)*$E3 + VLOOKUP("BMI",INDIRECT($B$1&"Coef"),1+MATCH($B$2,ModelTypes,0),FALSE)*$B$6 + VLOOKUP("Sex "&$B$7,INDIRECT($B$1&"Coef"),1+MATCH($B$2,ModelTypes,0),FALSE)))) -> 0.0081167338
A4: Other Factors | E4: 121 | F4: =1/(1+EXP(-1*(VLOOKUP("Intercept",INDIRECT($B$1&"Coef"),1+MATCH($B$2,ModelTypes,0),FALSE) + VLOOKUP("LDVMPH",INDIRECT($B$1&"Coef"),1+MATCH($B$2,ModelTypes,0),FALSE)*LN($B$5) + VLOOKUP(F$2,INDIRECT($B$1&"Coef"),1+MATCH($B$2,ModelTypes,0),FALSE) + VLOOKUP("Height",INDIRECT($B$1&"Coef"),1+MATCH($B$2,ModelTypes,0),FALSE)*$E4 + VLOOKUP("BMI",INDIRECT($B$1&"Coef"),1+MATCH($B$2,ModelTypes,0),FALSE)*$B$6 + VLOOKUP("Sex "&$B$7,INDIRECT($B$1&"Coef"),1+MATCH($B$2,ModelTypes,0),FALSE)))) -> 0.0060292953 | G4: =1/(1+EXP(-1*(VLOOKUP("Intercept",INDIRECT($B$1&"Coef"),1+MATCH($B$2,ModelTypes,0),FALSE) + VLOOKUP("LDVMPH",INDIRECT($B$1&"Coef"),1+MATCH($B$2,ModelTypes,0),FALSE)*LN($B$5) + VLOOKUP(G$2,INDIRECT($B$1&"Coef"),1+MATCH($B$2,ModelTypes,0),FALSE) + VLOOKUP("Height",INDIRECT($B$1&"Coef"),1+MATCH($B$2,ModelTypes,0),FALSE)*$E4 + VLOOKUP("BMI",INDIRECT($B$1&"Coef"),1+MATCH($B$2,ModelTypes,0),FALSE)*$B$6 + VLOOKUP("Sex "&$B$7,INDIRECT($B$1&"Coef"),1+MATCH($B$2,ModelTypes,0),FALSE)))) -> 0.0056943082 | H4: =1/(1+EXP(-1*(VLOOKUP("Intercept",INDIRECT($B$1&"Coef"),1+MATCH($B$2,ModelTypes,0),FALSE) + VLOOKUP("LDVMPH",INDIRECT($B$1&"Coef"),1+MATCH($B$2,ModelTypes,0),FALSE)*LN($B$5) + VLOOKUP(H$2,INDIRECT($B$1&"Coef"),1+MATCH($B$2,ModelTypes,0),FALSE) + VLOOKUP("Height",INDIRECT($B$1&"Coef"),1+MATCH($B$2,ModelTypes,0),FALSE)*$E4 + VLOOKUP("BMI",INDIRECT($B$1&"Coef"),1+MATCH($B$2,ModelTypes,0),FALSE)*$B$6 + VLOOKUP("Sex "&$B$7,INDIRECT($B$1&"Coef"),1+MATCH($B$2,ModelTypes,0),FALSE)))) -> 0.0083635167
A5: Delta-V (mph) | B5: 35 | E5: 122 | F5: =1/(1+EXP(-1*(VLOOKUP("Intercept",INDIRECT($B$1&"Coef"),1+MATCH($B$2,ModelTypes,0),FALSE) + VLOOKUP("LDVMPH",INDIRECT($B$1&"Coef"),1+MATCH($B$2,ModelTypes,0),FALSE)*LN($B$5) + VLOOKUP(F$2,INDIRECT($B$1&"Coef"),1+MATCH($B$2,ModelTypes,0),FALSE) + VLOOKUP("Height",INDIRECT($B$1&"Coef"),1+MATCH($B$2,ModelTypes,0),FALSE)*$E5 + VLOOKUP("BMI",INDIRECT($B$1&"Coef"),1+MATCH($B$2,ModelTypes,0),FALSE)*$B$6 + VLOOKUP("Sex "&$B$7,INDIRECT($B$1&"Coef"),1+MATCH($B$2,ModelTypes,0),FALSE)))) -> 0.0062130089 | G5: =1/(1+EXP(-1*(VLOOKUP("Intercept",INDIRECT($B$1&"Coef"),1+MATCH($B$2,ModelTypes,0),FALSE) + VLOOKUP("LDVMPH",INDIRECT($B$1&"Coef"),1+MATCH($B$2,ModelTypes,0),FALSE)*LN($B$5) + VLOOKUP(G$2,INDIRECT($B$1&"Coef"),1+MATCH($B$2,ModelTypes,0),FALSE) + VLOOKUP("Height",INDIRECT($B$1&"Coef"),1+MATCH($B$2,ModelTypes,0),FALSE)*$E5 + VLOOKUP("BMI",INDIRECT($B$1&"Coef"),1+MATCH($B$2,ModelTypes,0),FALSE)*$B$6 + VLOOKUP("Sex "&$B$7,INDIRECT($B$1&"Coef"),1+MATCH($B$2,ModelTypes,0),FALSE)))) -> 0.0058678748 | H5: =1/(1+EXP(-1*(VLOOKUP("Intercept",INDIRECT($B$1&"Coef"),1+MATCH($B$2,ModelTypes,0),FALSE) + VLOOKUP("LDVMPH",INDIRECT($B$1&"Coef"),1+MATCH($B$2,ModelTypes,0),FALSE)*LN($B$5) + VLOOKUP(H$2,INDIRECT($B$1&"Coef"),1+MATCH($B$2,ModelTypes,0),FALSE) + VLOOKUP("Height",INDIRECT($B$1&"Coef"),1+MATCH($B$2,ModelTypes,0),FALSE)*$E5 + VLOOKUP("BMI",INDIRECT($B$1&"Coef"),1+MATCH($B$2,ModelTypes,0),FALSE)*$B$6 + VLOOKUP("Sex "&$B$7,INDIRECT($B$1&"Coef"),1+MATCH($B$2,ModelTypes,0),FALSE)))) -> 0.0086177377
A6: BMI | B6: 20 | E6: 123 | F6: =1/(1+EXP(-1*(VLOOKUP("Intercept",INDIRECT($B$1&"Coef"),1+MATCH($B$2,ModelTypes,0),FALSE) + VLOOKUP("LDVMPH",INDIRECT($B$1&"Coef"),1+MATCH($B$2,ModelTypes,0),FALSE)*LN($B$5) + VLOOKUP(F$2,INDIRECT($B$1&"Coef"),1+MATCH($B$2,ModelTypes,0),FALSE) + VLOOKUP("Height",INDIRECT($B$1&"Coef"),1+MATCH($B$2,ModelTypes,0),FALSE)*$E6 + VLOOKUP("BMI",INDIRECT($B$1&"Coef"),1+MATCH($B$2,ModelTypes,0),FALSE)*$B$6 + VLOOKUP("Sex "&$B$7,INDIRECT($B$1&"Coef"),1+MATCH($B$2,ModelTypes,0),FALSE)))) -> 0.0064022841 | G6: =1/(1+EXP(-1*(VLOOKUP("Intercept",INDIRECT($B$1&"Coef"),1+MATCH($B$2,ModelTypes,0),FALSE) + VLOOKUP("LDVMPH",INDIRECT($B$1&"Coef"),1+MATCH($B$2,ModelTypes,0),FALSE)*LN($B$5) + VLOOKUP(G$2,INDIRECT($B$1&"Coef"),1+MATCH($B$2,ModelTypes,0),FALSE) + VLOOKUP("Height",INDIRECT($B$1&"Coef"),1+MATCH($B$2,ModelTypes,0),FALSE)*$E6 + VLOOKUP("BMI",INDIRECT($B$1&"Coef"),1+MATCH($B$2,ModelTypes,0),FALSE)*$B$6 + VLOOKUP("Sex "&$B$7,INDIRECT($B$1&"Coef"),1+MATCH($B$2,ModelTypes,0),FALSE)))) -> 0.0060466998 | H6: =1/(1+EXP(-1*(VLOOKUP("Intercept",INDIRECT($B$1&"Coef"),1+MATCH($B$2,ModelTypes,0),FALSE) + VLOOKUP("LDVMPH",INDIRECT($B$1&"Coef"),1+MATCH($B$2,ModelTypes,0),FALSE)*LN($B$5) + VLOOKUP(H$2,INDIRECT($B$1&"Coef"),1+MATCH($B$2,ModelTypes,0),FALSE) + VLOOKUP("Height",INDIRECT($B$1&"Coef"),1+MATCH($B$2,ModelTypes,0),FALSE)*$E6 + VLOOKUP("BMI",INDIRECT($B$1&"Coef"),1+MATCH($B$2,ModelTypes,0),FALSE)*$B$6 + VLOOKUP("Sex "&$B$7,INDIRECT($B$1&"Coef"),1+MATCH($B$2,ModelTypes,0),FALSE)))) -> 0.0088796169
A7: Sex | B7: F | E7: 124 | F7: =1/(1+EXP(-1*(VLOOKUP("Intercept",INDIRECT($B$1&"Coef"),1+MATCH($B$2,ModelTypes,0),FALSE) + VLOOKUP("LDVMPH",INDIRECT($B$1&"Coef"),1+MATCH($B$2,ModelTypes,0),FALSE)*LN($B$5) + VLOOKUP(F$2,INDIRECT($B$1&"Coef"),1+MATCH($B$2,ModelTypes,0),FALSE) + VLOOKUP("Height",INDIRECT($B$1&"Coef"),1+MATCH($B$2,ModelTypes,0),FALSE)*$E7 + VLOOKUP("BMI",INDIRECT($B$1&"Coef"),1+MATCH($B$2,ModelTypes,0),FALSE)*$B$6 + VLOOKUP("Sex "&$B$7,INDIRECT($B$1&"Coef"),1+MATCH($B$2,ModelTypes,0),FALSE)))) -> 0.0065972873 | G7: =1/(1+EXP(-1*(VLOOKUP("Intercept",INDIRECT($B$1&"Coef"),1+MATCH($B$2,ModelTypes,0),FALSE) + VLOOKUP("LDVMPH",INDIRECT($B$1&"Coef"),1+MATCH($B$2,ModelTypes,0),FALSE)*LN($B$5) + VLOOKUP(G$2,INDIRECT($B$1&"Coef"),1+MATCH($B$2,ModelTypes,0),FALSE) + VLOOKUP("Height",INDIRECT($B$1&"Coef"),1+MATCH($B$2,ModelTypes,0),FALSE)*$E7 + VLOOKUP("BMI",INDIRECT($B$1&"Coef"),1+MATCH($B$2,ModelTypes,0),FALSE)*$B$6 + VLOOKUP("Sex "&$B$7,INDIRECT($B$1&"Coef"),1+MATCH($B$2,ModelTypes,0),FALSE)))) -> 0.0062309403 | H7: =1/(1+EXP(-1*(VLOOKUP("Intercept",INDIRECT($B$1&"Coef"),1+MATCH($B$2,ModelTypes,0),FALSE) + VLOOKUP("LDVMPH",INDIRECT($B$1&"Coef"),1+MATCH($B$2,ModelTypes,0),FALSE)*LN($B$5) + VLOOKUP(H$2,INDIRECT($B$1&"Coef"),1+MATCH($B$2,ModelTypes,0),FALSE) + VLOOKUP("Height",INDIRECT($B$1&"Coef"),1+MATCH($B$2,ModelTypes,0),FALSE)*$E7 + VLOOKUP("BMI",INDIRECT($B$1&"Coef"),1+MATCH($B$2,ModelTypes,0),FALSE)*$B$6 + VLOOKUP("Sex "&$B$7,INDIRECT($B$1&"Coef"),1+MATCH($B$2,ModelTypes,0),FALSE)))) -> 0.0091493807
E8: 125 | F8: =1/(1+EXP(-1*(VLOOKUP("Intercept",INDIRECT($B$1&"Coef"),1+MATCH($B$2,ModelTypes,0),FALSE) + VLOOKUP("LDVMPH",INDIRECT($B$1&"Coef"),1+MATCH($B$2,ModelTypes,0),FALSE)*LN($B$5) + VLOOKUP(F$2,INDIRECT($B$1&"Coef"),1+MATCH($B$2,ModelTypes,0),FALSE) + VLOOKUP("Height",INDIRECT($B$1&"Coef"),1+MATCH($B$2,ModelTypes,0),FALSE)*$E8 + VLOOKUP("BMI",INDIRECT($B$1&"Coef"),1+MATCH($B$2,ModelTypes,0),FALSE)*$B$6 + VLOOKUP("Sex "&$B$7,INDIRECT($B$1&"Coef"),1+MATCH($B$2,ModelTypes,0),FALSE)))) -> 0.0067981892 | G8: =1/(1+EXP(-1*(VLOOKUP("Intercept",INDIRECT($B$1&"Coef"),1+MATCH($B$2,ModelTypes,0),FALSE) + VLOOKUP("LDVMPH",INDIRECT($B$1&"Coef"),1+MATCH($B$2,ModelTypes,0),FALSE)*LN($B$5) + VLOOKUP(G$2,INDIRECT($B$1&"Coef"),1+MATCH($B$2,ModelTypes,0),FALSE) + VLOOKUP("Height",INDIRECT($B$1&"Coef"),1+MATCH($B$2,ModelTypes,0),FALSE)*$E8 + VLOOKUP("BMI",INDIRECT($B$1&"Coef"),1+MATCH($B$2,ModelTypes,0),FALSE)*$B$6 + VLOOKUP("Sex "&$B$7,INDIRECT($B$1&"Coef"),1+MATCH($B$2,ModelTypes,0),FALSE)))) -> 0.0064207583 | H8: =1/(1+EXP(-1*(VLOOKUP("Intercept",INDIRECT($B$1&"Coef"),1+MATCH($B$2,ModelTypes,0),FALSE) + VLOOKUP("LDVMPH",INDIRECT($B$1&"Coef"),1+MATCH($B$2,ModelTypes,0),FALSE)*LN($B$5) + VLOOKUP(H$2,INDIRECT($B$1&"Coef"),1+MATCH($B$2,ModelTypes,0),FALSE) + VLOOKUP("Height",INDIRECT($B$1&"Coef"),1+MATCH($B$2,ModelTypes,0),FALSE)*$E8 + VLOOKUP("BMI",INDIRECT($B$1&"Coef"),1+MATCH($B$2,ModelTypes,0),FALSE)*$B$6 + VLOOKUP("Sex "&$B$7,INDIRECT($B$1&"Coef"),1+MATCH($B$2,ModelTypes,0),FALSE)))) -> 0.009427262
E9: 126 | F9: =1/(1+EXP(-1*(VLOOKUP("Intercept",INDIRECT($B$1&"Coef"),1+MATCH($B$2,ModelTypes,0),FALSE) + VLOOKUP("LDVMPH",INDIRECT($B$1&"Coef"),1+MATCH($B$2,ModelTypes,0),FALSE)*LN($B$5) + VLOOKUP(F$2,INDIRECT($B$1&"Coef"),1+MATCH($B$2,ModelTypes,0),FALSE) + VLOOKUP("Height",INDIRECT($B$1&"Coef"),1+MATCH($B$2,ModelTypes,0),FALSE)*$E9 + VLOOKUP("BMI",INDIRECT($B$1&"Coef"),1+MATCH($B$2,ModelTypes,0),FALSE)*$B$6 + VLOOKUP("Sex "&$B$7,INDIRECT($B$1&"Coef"),1+MATCH($B$2,ModelTypes,0),FALSE)))) -> 0.007005166 | G9: =1/(1+EXP(-1*(VLOOKUP("Intercept",INDIRECT($B$1&"Coef"),1+MATCH($B$2,ModelTypes,0),FALSE) + VLOOKUP("LDVMPH",INDIRECT($B$1&"Coef"),1+MATCH($B$2,ModelTypes,0),FALSE)*LN($B$5) + VLOOKUP(G$2,INDIRECT($B$1&"Coef"),1+MATCH($B$2,ModelTypes,0),FALSE) + VLOOKUP("Height",INDIRECT($B$1&"Coef"),1+MATCH($B$2,ModelTypes,0),FALSE)*$E9 + VLOOKUP("BMI",INDIRECT($B$1&"Coef"),1+MATCH($B$2,ModelTypes,0),FALSE)*$B$6 + VLOOKUP("Sex "&$B$7,INDIRECT($B$1&"Coef"),1+MATCH($B$2,ModelTypes,0),FALSE)))) -> 0.0066163204 | H9: =1/(1+EXP(-1*(VLOOKUP("Intercept",INDIRECT($B$1&"Coef"),1+MATCH($B$2,ModelTypes,0),FALSE) + VLOOKUP("LDVMPH",INDIRECT($B$1&"Coef"),1+MATCH($B$2,ModelTypes,0),FALSE)*LN($B$5) + VLOOKUP(H$2,INDIRECT($B$1&"Coef"),1+MATCH($B$2,ModelTypes,0),FALSE) + VLOOKUP("Height",INDIRECT($B$1&"Coef"),1+MATCH($B$2,ModelTypes,0),FALSE)*$E9 + VLOOKUP("BMI",INDIRECT($B$1&"Coef"),1+MATCH($B$2,ModelTypes,0),FALSE)*$B$6 + VLOOKUP("Sex "&$B$7,INDIRECT($B$1&"Coef"),1+MATCH($B$2,ModelTypes,0),FALSE)))) -> 0.0097135003
E10: 127 | F10: =1/(1+EXP(-1*(VLOOKUP("Intercept",INDIRECT($B$1&"Coef"),1+MATCH($B$2,ModelTypes,0),FALSE) + VLOOKUP("LDVMPH",INDIRECT($B$1&"Coef"),1+MATCH($B$2,ModelTypes,0),FALSE)*LN($B$5) + VLOOKUP(F$2,INDIRECT($B$1&"Coef"),1+MATCH($B$2,ModelTypes,0),FALSE) + VLOOKUP("Height",INDIRECT($B$1&"Coef"),1+MATCH($B$2,ModelTypes,0),FALSE)*$E10 + VLOOKUP("BMI",INDIRECT($B$1&"Coef"),1+MATCH($B$2,ModelTypes,0),FALSE)*$B$6 + VLOOKUP("Sex "&$B$7,INDIRECT($B$1&"Coef"),1+MATCH($B$2,ModelTypes,0),FALSE)))) -> 0.0072183985 | G10: =1/(1+EXP(-1*(VLOOKUP("Intercept",INDIRECT($B$1&"Coef"),1+MATCH($B$2,ModelTypes,0),FALSE) + VLOOKUP("LDVMPH",INDIRECT($B$1&"Coef"),1+MATCH($B$2,ModelTypes,0),FALSE)*LN($B$5) + VLOOKUP(G$2,INDIRECT($B$1&"Coef"),1+MATCH($B$2,ModelTypes,0),FALSE) + VLOOKUP("Height",INDIRECT($B$1&"Coef"),1+MATCH($B$2,ModelTypes,0),FALSE)*$E10 + VLOOKUP("BMI",INDIRECT($B$1&"Coef"),1+MATCH($B$2,ModelTypes,0),FALSE)*$B$6 + VLOOKUP("Sex "&$B$7,INDIRECT($B$1&"Coef"),1+MATCH($B$2,ModelTypes,0),FALSE)))) -> 0.006817798 | H10: =1/(1+EXP(-1*(VLOOKUP("Intercept",INDIRECT($B$1&"Coef"),1+MATCH($B$2,ModelTypes,0),FALSE) + VLOOKUP("LDVMPH",INDIRECT($B$1&"Coef"),1+MATCH($B$2,ModelTypes,0),FALSE)*LN($B$5) + VLOOKUP(H$2,INDIRECT($B$1&"Coef"),1+MATCH($B$2,ModelTypes,0),FALSE) + VLOOKUP("Height",INDIRECT($B$1&"Coef"),1+MATCH($B$2,ModelTypes,0),FALSE)*$E10 + VLOOKUP("BMI",INDIRECT($B$1&"Coef"),1+MATCH($B$2,ModelTypes,0),FALSE)*$B$6 + VLOOKUP("Sex "&$B$7,INDIRECT($B$1&"Coef"),1+MATCH($B$2,ModelTypes,0),FALSE)))) -> 0.010008342
E11: 128 | F11: =1/(1+EXP(-1*(VLOOKUP("Intercept",INDIRECT($B$1&"Coef"),1+MATCH($B$2,ModelTypes,0),FALSE) + VLOOKUP("LDVMPH",INDIRECT($B$1&"Coef"),1+MATCH($B$2,ModelTypes,0),FALSE)*LN($B$5) + VLOOKUP(F$2,INDIRECT($B$1&"Coef"),1+MATCH($B$2,ModelTypes,0),FALSE) + VLOOKUP("Height",INDIRECT($B$1&"Coef"),1+MATCH($B$2,ModelTypes,0),FALSE)*$E11 + VLOOKUP("BMI",INDIRECT($B$1&"Coef"),1+MATCH($B$2,ModelTypes,0),FALSE)*$B$6 + VLOOKUP("Sex "&$B$7,INDIRECT($B$1&"Coef"),1+MATCH($B$2,ModelTypes,0),FALSE)))) -> 0.007438073 | G11: =1/(1+EXP(-1*(VLOOKUP("Intercept",INDIRECT($B$1&"Coef"),1+MATCH($B$2,ModelTypes,0),FALSE) + VLOOKUP("LDVMPH",INDIRECT($B$1&"Coef"),1+MATCH($B$2,ModelTypes,0),FALSE)*LN($B$5) + VLOOKUP(G$2,INDIRECT($B$1&"Coef"),1+MATCH($B$2,ModelTypes,0),FALSE) + VLOOKUP("Height",INDIRECT($B$1&"Coef"),1+MATCH($B$2,ModelTypes,0),FALSE)*$E11 + VLOOKUP("BMI",INDIRECT($B$1&"Coef"),1+MATCH($B$2,ModelTypes,0),FALSE)*$B$6 + VLOOKUP("Sex "&$B$7,INDIRECT($B$1&"Coef"),1+MATCH($B$2,ModelTypes,0),FALSE)))) -> 0.0070253675 | H11: =1/(1+EXP(-1*(VLOOKUP("Intercept",INDIRECT($B$1&"Coef"),1+MATCH($B$2,ModelTypes,0),FALSE) + VLOOKUP("LDVMPH",INDIRECT($B$1&"Coef"),1+MATCH($B$2,ModelTypes,0),FALSE)*LN($B$5) + VLOOKUP(H$2,INDIRECT($B$1&"Coef"),1+MATCH($B$2,ModelTypes,0),FALSE) + VLOOKUP("Height",INDIRECT($B$1&"Coef"),1+MATCH($B$2,ModelTypes,0),FALSE)*$E11 + VLOOKUP("BMI",INDIRECT($B$1&"Coef"),1+MATCH($B$2,ModelTypes,0),FALSE)*$B$6 + VLOOKUP("Sex "&$B$7,INDIRECT($B$1&"Coef"),1+MATCH($B$2,ModelTypes,0),FALSE)))) -> 0.01031204
E12: 129 | F12: =1/(1+EXP(-1*(VLOOKUP("Intercept",INDIRECT($B$1&"Coef"),1+MATCH($B$2,ModelTypes,0),FALSE) + VLOOKUP("LDVMPH",INDIRECT($B$1&"Coef"),1+MATCH($B$2,ModelTypes,0),FALSE)*LN($B$5) + VLOOKUP(F$2,INDIRECT($B$1&"Coef"),1+MATCH($B$2,ModelTypes,0),FALSE) + VLOOKUP("Height",INDIRECT($B$1&"Coef"),1+MATCH($B$2,ModelTypes,0),FALSE)*$E12 + VLOOKUP("BMI",INDIRECT($B$1&"Coef"),1+MATCH($B$2,ModelTypes,0),FALSE)*$B$6 + VLOOKUP("Sex "&$B$7,INDIRECT($B$1&"Coef"),1+MATCH($B$2,ModelTypes,0),FALSE)))) -> 0.0076643813 | G12: =1/(1+EXP(-1*(VLOOKUP("Intercept",INDIRECT($B$1&"Coef"),1+MATCH($B$2,ModelTypes,0),FALSE) + VLOOKUP("LDVMPH",INDIRECT($B$1&"Coef"),1+MATCH($B$2,ModelTypes,0),FALSE)*LN($B$5) + VLOOKUP(G$2,INDIRECT($B$1&"Coef"),1+MATCH($B$2,ModelTypes,0),FALSE) + VLOOKUP("Height",INDIRECT($B$1&"Coef"),1+MATCH($B$2,ModelTypes,0),FALSE)*$E12 + VLOOKUP("BMI",INDIRECT($B$1&"Coef"),1+MATCH($B$2,ModelTypes,0),FALSE)*$B$6 + VLOOKUP("Sex "&$B$7,INDIRECT($B$1&"Coef"),1+MATCH($B$2,ModelTypes,0),FALSE)))) -> 0.0072392105 | H12: =1/(1+EXP(-1*(VLOOKUP("Intercept",INDIRECT($B$1&"Coef"),1+MATCH($B$2,ModelTypes,0),FALSE) + VLOOKUP("LDVMPH",INDIRECT($B$1&"Coef"),1+MATCH($B$2,ModelTypes,0),FALSE)*LN($B$5) + VLOOKUP(H$2,INDIRECT($B$1&"Coef"),1+MATCH($B$2,ModelTypes,0),FALSE) + VLOOKUP("Height",INDIRECT($B$1&"Coef"),1+MATCH($B$2,ModelTypes,0),FALSE)*$E12 + VLOOKUP("BMI",INDIRECT($B$1&"Coef"),1+MATCH($B$2,ModelTypes,0),FALSE)*$B$6 + VLOOKUP("Sex "&$B$7,INDIRECT($B$1&"Coef"),1+MATCH($B$2,ModelTypes,0),FALSE)))) -> 0.010624854
E13: 130 | F13: =1/(1+EXP(-1*(VLOOKUP("Intercept",INDIRECT($B$1&"Coef"),1+MATCH($B$2,ModelTypes,0),FALSE) + VLOOKUP("LDVMPH",INDIRECT($B$1&"Coef"),1+MATCH($B$2,ModelTypes,0),FALSE)*LN($B$5) + VLOOKUP(F$2,INDIRECT($B$1&"Coef"),1+MATCH($B$2,ModelTypes,0),FALSE) + VLOOKUP("Height",INDIRECT($B$1&"Coef"),1+MATCH($B$2,ModelTypes,0),FALSE)*$E13 + VLOOKUP("BMI",INDIRECT($B$1&"Coef"),1+MATCH($B$2,ModelTypes,0),FALSE)*$B$6 + VLOOKUP("Sex "&$B$7,INDIRECT($B$1&"Coef"),1+MATCH($B$2,ModelTypes,0),FALSE)))) -> 0.0078975203 | G13: =1/(1+EXP(-1*(VLOOKUP("Intercept",INDIRECT($B$1&"Coef"),1+MATCH($B$2,ModelTypes,0),FALSE) + VLOOKUP("LDVMPH",INDIRECT($B$1&"Coef"),1+MATCH($B$2,ModelTypes,0),FALSE)*LN($B$5) + VLOOKUP(G$2,INDIRECT($B$1&"Coef"),1+MATCH($B$2,ModelTypes,0),FALSE) + VLOOKUP("Height",INDIRECT($B$1&"Coef"),1+MATCH($B$2,ModelTypes,0),FALSE)*$E13 + VLOOKUP("BMI",INDIRECT($B$1&"Coef"),1+MATCH($B$2,ModelTypes,0),FALSE)*$B$6 + VLOOKUP("Sex "&$B$7,INDIRECT($B$1&"Coef"),1+MATCH($B$2,ModelTypes,0),FALSE)))) -> 0.0074595136 | H13: =1/(1+EXP(-1*(VLOOKUP("Intercept",INDIRECT($B$1&"Coef"),1+MATCH($B$2,ModelTypes,0),FALSE) + VLOOKUP("LDVMPH",INDIRECT($B$1&"Coef"),1+MATCH($B$2,ModelTypes,0),FALSE)*LN($B$5) + VLOOKUP(H$2,INDIRECT($B$1&"Coef"),1+MATCH($B$2,ModelTypes,0),FALSE) + VLOOKUP("Height",INDIRECT($B$1&"Coef"),1+MATCH($B$2,ModelTypes,0),FALSE)*$E13 + VLOOKUP("BMI",INDIRECT($B$1&"Coef"),1+MATCH($B$2,ModelTypes,0),FALSE)*$B$6 + VLOOKUP("Sex "&$B$7,INDIRECT($B$1&"Coef"),1+MATCH($B$2,ModelTypes,0),FALSE)))) -> 0.010947053
E14: 131 | F14: =1/(1+EXP(-1*(VLOOKUP("Intercept",INDIRECT($B$1&"Coef"),1+MATCH($B$2,ModelTypes,0),FALSE) + VLOOKUP("LDVMPH",INDIRECT($B$1&"Coef"),1+MATCH($B$2,ModelTypes,0),FALSE)*LN($B$5) + VLOOKUP(F$2,INDIRECT($B$1&"Coef"),1+MATCH($B$2,ModelTypes,0),FALSE) + VLOOKUP("Height",INDIRECT($B$1&"Coef"),1+MATCH($B$2,ModelTypes,0),FALSE)*$E14 + VLOOKUP("BMI",INDIRECT($B$1&"Coef"),1+MATCH($B$2,ModelTypes,0),FALSE)*$B$6 + VLOOKUP("Sex "&$B$7,INDIRECT($B$1&"Coef"),1+MATCH($B$2,ModelTypes,0),FALSE)))) -> 0.0081376928 | G14: =1/(1+EXP(-1*(VLOOKUP("Intercept",INDIRECT($B$1&"Coef"),1+MATCH($B$2,ModelTypes,0),FALSE) + VLOOKUP("LDVMPH",INDIRECT($B$1&"Coef"),1+MATCH($B$2,ModelTypes,0),FALSE)*LN($B$5) + VLOOKUP(G$2,INDIRECT($B$1&"Coef"),1+MATCH($B$2,ModelTypes,0),FALSE) + VLOOKUP("Height",INDIRECT($B$1&"Coef"),1+MATCH($B$2,ModelTypes,0),FALSE)*$E14 + VLOOKUP("BMI",INDIRECT($B$1&"Coef"),1+MATCH($B$2,ModelTypes,0),FALSE)*$B$6 + VLOOKUP("Sex "&$B$7,INDIRECT($B$1&"Coef"),1+MATCH($B$2,ModelTypes,0),FALSE)))) -> 0.0076864691 | H14: =1/(1+EXP(-1*(VLOOKUP("Intercept",INDIRECT($B$1&"Coef"),1+MATCH($B$2,ModelTypes,0),FALSE) + VLOOKUP("LDVMPH",INDIRECT($B$1&"Coef"),1+MATCH($B$2,ModelTypes,0),FALSE)*LN($B$5) + VLOOKUP(H$2,INDIRECT($B$1&"Coef"),1+MATCH($B$2,ModelTypes,0),FALSE) + VLOOKUP("Height",INDIRECT($B$1&"Coef"),1+MATCH($B$2,ModelTypes,0),FALSE)*$E14 + VLOOKUP("BMI",INDIRECT($B$1&"Coef"),1+MATCH($B$2,ModelTypes,0),FALSE)*$B$6 + VLOOKUP("Sex "&$B$7,INDIRECT($B$1&"Coef"),1+MATCH($B$2,ModelTypes,0),FALSE)))) -> 0.011278911
E15: 132 | F15: =1/(1+EXP(-1*(VLOOKUP("Intercept",INDIRECT($B$1&"Coef"),1+MATCH($B$2,ModelTypes,0),FALSE) + VLOOKUP("LDVMPH",INDIRECT($B$1&"Coef"),1+MATCH($B$2,ModelTypes,0),FALSE)*LN($B$5) + VLOOKUP(F$2,INDIRECT($B$1&"Coef"),1+MATCH($B$2,ModelTypes,0),FALSE) + VLOOKUP("Height",INDIRECT($B$1&"Coef"),1+MATCH($B$2,ModelTypes,0),FALSE)*$E15 + VLOOKUP("BMI",INDIRECT($B$1&"Coef"),1+MATCH($B$2,ModelTypes,0),FALSE)*$B$6 + VLOOKUP("Sex "&$B$7,INDIRECT($B$1&"Coef"),1+MATCH($B$2,ModelTypes,0),FALSE)))) -> 0.0083851076 | G15: =1/(1+EXP(-1*(VLOOKUP("Intercept",INDIRECT($B$1&"Coef"),1+MATCH($B$2,ModelTypes,0),FALSE) + VLOOKUP("LDVMPH",INDIRECT($B$1&"Coef"),1+MATCH($B$2,ModelTypes,0),FALSE)*LN($B$5) + VLOOKUP(G$2,INDIRECT($B$1&"Coef"),1+MATCH($B$2,ModelTypes,0),FALSE) + VLOOKUP("Height",INDIRECT($B$1&"Coef"),1+MATCH($B$2,ModelTypes,0),FALSE)*$E15 + VLOOKUP("BMI",INDIRECT($B$1&"Coef"),1+MATCH($B$2,ModelTypes,0),FALSE)*$B$6 + VLOOKUP("Sex "&$B$7,INDIRECT($B$1&"Coef"),1+MATCH($B$2,ModelTypes,0),FALSE)))) -> 0.0079202746 | H15: =1/(1+EXP(-1*(VLOOKUP("Intercept",INDIRECT($B$1&"Coef"),1+MATCH($B$2,ModelTypes,0),FALSE) + VLOOKUP("LDVMPH",INDIRECT($B$1&"Coef"),1+MATCH($B$2,ModelTypes,0),FALSE)*LN($B$5) + VLOOKUP(H$2,INDIRECT($B$1&"Coef"),1+MATCH($B$2,ModelTypes,0),FALSE) + VLOOKUP("Height",INDIRECT($B$1&"Coef"),1+MATCH($B$2,ModelTypes,0),FALSE)*$E15 + VLOOKUP("BMI",INDIRECT($B$1&"Coef"),1+MATCH($B$2,ModelTypes,0),FALSE)*$B$6 + VLOOKUP("Sex "&$B$7,INDIRECT($B$1&"Coef"),1+MATCH($B$2,ModelTypes,0),FALSE)))) -> 0.011620711
E16: 133 | F16: =1/(1+EXP(-1*(VLOOKUP("Intercept",INDIRECT($B$1&"Coef"),1+MATCH($B$2,ModelTypes,0),FALSE) + VLOOKUP("LDVMPH",INDIRECT($B$1&"Coef"),1+MATCH($B$2,ModelTypes,0),FALSE)*LN($B$5) + VLOOKUP(F$2,INDIRECT($B$1&"Coef"),1+MATCH($B$2,ModelTypes,0),FALSE) + VLOOKUP("Height",INDIRECT($B$1&"Coef"),1+MATCH($B$2,ModelTypes,0),FALSE)*$E16 + VLOOKUP("BMI",INDIRECT($B$1&"Coef"),1+MATCH($B$2,ModelTypes,0),FALSE)*$B$6 + VLOOKUP("Sex "&$B$7,INDIRECT($B$1&"Coef"),1+MATCH($B$2,ModelTypes,0),FALSE)))) -> 0.0086399791 | G16: =1/(1+EXP(-1*(VLOOKUP("Intercept",INDIRECT($B$1&"Coef"),1+MATCH($B$2,ModelTypes,0),FALSE) + VLOOKUP("LDVMPH",INDIRECT($B$1&"Coef"),1+MATCH($B$2,ModelTypes,0),FALSE)*LN($B$5) + VLOOKUP(G$2,INDIRECT($B$1&"Coef"),1+MATCH($B$2,ModelTypes,0),FALSE) + VLOOKUP("Height",INDIRECT($B$1&"Coef"),1+MATCH($B$2,ModelTypes,0),FALSE)*$E16 + VLOOKUP("BMI",INDIRECT($B$1&"Coef"),1+MATCH($B$2,ModelTypes,0),FALSE)*$B$6 + VLOOKUP("Sex "&$B$7,INDIRECT($B$1&"Coef"),1+MATCH($B$2,ModelTypes,0),FALSE)))) -> 0.0081611335 | H16: =1/(1+EXP(-1*(VLOOKUP("Intercept",INDIRECT($B$1&"Coef"),1+MATCH($B$2,ModelTypes,0),FALSE) + VLOOKUP("LDVMPH",INDIRECT($B$1&"Coef"),1+MATCH($B$2,ModelTypes,0),FALSE)*LN($B$5) + VLOOKUP(H$2,INDIRECT($B$1&"Coef"),1+MATCH($B$2,ModelTypes,0),FALSE) + VLOOKUP("Height",INDIRECT($B$1&"Coef"),1+MATCH($B$2,ModelTypes,0),FALSE)*$E16 + VLOOKUP("BMI",INDIRECT($B$1&"Coef"),1+MATCH($B$2,ModelTypes,0),FALSE)*$B$6 + VLOOKUP("Sex "&$B$7,INDIRECT($B$1&"Coef"),1+MATCH($B$2,ModelTypes,0),FALSE)))) -> 0.011972744
